<?xml version="1.0" ?>
<!-- =================================================================================== -->
<!-- |    This document was autogenerated by xacro from sdh2.xacro                     | -->
<!-- |    EDITING THIS FILE BY HAND IS NOT RECOMMENDED                                 | -->
<!-- =================================================================================== -->
<robot name="lbr" xmlns:controller="http://playerstage.sourceforge.net/gazebo/xmlschema/#controller" xmlns:interface="http://playerstage.sourceforge.net/gazebo/xmlschema/#interface" xmlns:sensor="http://playerstage.sourceforge.net/gazebo/xmlschema/#sensor" xmlns:xacro="http://ros.org/wiki/xacro">
  <material name="Schunk/LightGrey">
    <color rgba="0.7 0.7 0.7 1.0"/>
  </material>
  <material name="Schunk/DarkGrey">
    <color rgba="0.4 0.4 0.4 1.0"/>
  </material>
  <material name="Schunk/Black">
    <color rgba="0.0 0.0 0.0 1.0"/>
  </material>
  <material name="Schunk/DarkGolden">
    <color rgba="0.4 0.4 0.3 1.0"/>
  </material>
  <material name="Schunk/Blue">
    <color rgba="0.0 0.0 0.8 1.0"/>
  </material>
  <link name="sdh2_palm_link">
    <inertial>
      <origin rpy="0 0 0" xyz="0 0 0"/>
      <mass value="1"/>
      <inertia ixx="0.01" ixy="0" ixz="0" iyy="0.01" iyz="0" izz="0.01"/>
    </inertial>
    <visual>
      <origin rpy="0 0 0" xyz="0 0 0"/>
      <geometry>
        <mesh filename="package://sdh2_description/meshes/palm.stl"/>
      </geometry>
      <material name="Schunk/LightGrey"/>
    </visual>
    <collision>
      <origin rpy="0 0 0" xyz="0 0 0"/>
      <geometry>
        <mesh filename="package://sdh2_description/meshes/palm_low_res.stl"/>
      </geometry>
    </collision>
  </link>
  <joint name="sdh2_grasp_joint" type="fixed">
    <origin rpy="0 0 0" xyz="0 0 0.15"/>
    <parent link="sdh2_palm_link"/>
    <child link="sdh2_grasp_link"/>
  </joint>
  <link name="sdh2_grasp_link"/>
  <joint name="sdh2_tip_joint" type="fixed">
    <origin rpy="0 0 0" xyz="0 0 0.22"/>
    <parent link="sdh2_palm_link"/>
    <child link="sdh2_tip_link"/>
  </joint>
  <link name="sdh2_tip_link"/>
  <joint name="sdh2_knuckle_joint" type="revolute">
    <origin rpy="0 0 3.14159265" xyz="0.01905 0.033 0.0745"/>
    <parent link="sdh2_palm_link"/>
    <child link="sdh2_finger_11_link"/>
    <axis xyz="0 0 1"/>
    <dynamics damping="1"/>
    <limit effort="100" lower="0" upper="1.570796327" velocity="5"/>
  </joint>
  <link name="sdh2_finger_11_link">
    <inertial>
      <origin rpy="0 0 0" xyz="0 0 0"/>
      <mass value="0.1"/>
      <inertia ixx="0.01" ixy="0" ixz="0" iyy="0.01" iyz="0" izz="0.01"/>
    </inertial>
    <visual>
      <origin rpy="0 0 0" xyz="0 0 0"/>
      <geometry>
        <mesh filename="package://sdh2_description/meshes/knuckle.stl"/>
      </geometry>
      <material name="Schunk/LightGrey"/>
    </visual>
    <collision>
      <origin rpy="0 0 0" xyz="0 0 0"/>
      <geometry>
        <mesh filename="package://sdh2_description/meshes/knuckle_low_res.stl"/>
      </geometry>
    </collision>
  </link>
  <joint name="sdh2_finger_12_joint" type="revolute">
    <origin rpy="0 0 0" xyz="0 0 0.0165"/>
    <parent link="sdh2_finger_11_link"/>
    <child link="sdh2_finger_12_link"/>
    <axis xyz="0 1 0"/>
    <dynamics damping="1"/>
    <limit effort="100" lower="-1.570796327" upper="1.570796327" velocity="5"/>
  </joint>
  <link name="sdh2_finger_12_link">
    <inertial>
      <origin rpy="0 0 0" xyz="0 0 0"/>
      <mass value="0.1"/>
      <inertia ixx="0.01" ixy="0" ixz="0" iyy="0.01" iyz="0" izz="0.01"/>
    </inertial>
    <visual>
      <origin rpy="0 0 0" xyz="0 0 0"/>
      <geometry>
        <mesh filename="package://sdh2_description/meshes/finger.stl"/>
      </geometry>
      <material name="Schunk/LightGrey"/>
    </visual>
    <collision>
      <origin rpy="0 0 0" xyz="0 0 0"/>
      <geometry>
        <mesh filename="package://sdh2_description/meshes/finger_low_res.stl"/>
      </geometry>
    </collision>
  </link>
  <joint name="sdh2_finger_13_joint" type="revolute">
    <origin rpy="0 0 0" xyz="0 0 0.0865"/>
    <parent link="sdh2_finger_12_link"/>
    <child link="sdh2_finger_13_link"/>
    <axis xyz="0 1 0"/>
    <dynamics damping="1"/>
    <limit effort="100" lower="-1.570796327" upper="1.570796327" velocity="5"/>
  </joint>
  <link name="sdh2_finger_13_link">
    <inertial>
      <origin rpy="0 0 0" xyz="0 0 0"/>
      <mass value="0.1"/>
      <inertia ixx="0.01" ixy="0" ixz="0" iyy="0.01" iyz="0" izz="0.01"/>
    </inertial>
    <visual>
      <origin rpy="0 0 0" xyz="0 0 0"/>
      <geometry>
        <mesh filename="package://sdh2_description/meshes/finger_tip.stl"/>
      </geometry>
      <material name="Schunk/LightGrey"/>
    </visual>
    <collision>
      <origin rpy="0 0 0" xyz="0 0 0"/>
      <geometry>
        <mesh filename="package://sdh2_description/meshes/finger_tip_low_res.stl"/>
      </geometry>
    </collision>
  </link>
  <joint name="sdh2_finger_21_joint" type="revolute">
    <mimic joint="sdh2_knuckle_joint" multiplier="1" offset="0"/>
    <origin rpy="0 0 3.14159265" xyz="0.01905 -0.033 0.0745"/>
    <parent link="sdh2_palm_link"/>
    <child link="sdh2_finger_21_link"/>
    <axis xyz="0 0 -1"/>
    <dynamics damping="1"/>
    <limit effort="100" lower="0" upper="1.570796327" velocity="5"/>
  </joint>
  <link name="sdh2_finger_21_link">
    <inertial>
      <origin rpy="0 0 0" xyz="0 0 0"/>
      <mass value="0.1"/>
      <inertia ixx="0.01" ixy="0" ixz="0" iyy="0.01" iyz="0" izz="0.01"/>
    </inertial>
    <visual>
      <origin rpy="0 0 0" xyz="0 0 0"/>
      <geometry>
        <mesh filename="package://sdh2_description/meshes/knuckle.stl"/>
      </geometry>
      <material name="Schunk/LightGrey"/>
    </visual>
    <collision>
      <origin rpy="0 0 0" xyz="0 0 0"/>
      <geometry>
        <mesh filename="package://sdh2_description/meshes/knuckle_low_res.stl"/>
      </geometry>
    </collision>
  </link>
  <joint name="sdh2_finger_22_joint" type="revolute">
    <origin rpy="0 0 0" xyz="0 0 0.0165"/>
    <parent link="sdh2_finger_21_link"/>
    <child link="sdh2_finger_22_link"/>
    <axis xyz="0 1 0"/>
    <dynamics damping="1"/>
    <limit effort="100" lower="-1.570796327" upper="1.570796327" velocity="5"/>
  </joint>
  <link name="sdh2_finger_22_link">
    <inertial>
      <origin rpy="0 0 0" xyz="0 0 0"/>
      <mass value="0.1"/>
      <inertia ixx="0.01" ixy="0" ixz="0" iyy="0.01" iyz="0" izz="0.01"/>
    </inertial>
    <visual>
      <origin rpy="0 0 0" xyz="0 0 0"/>
      <geometry>
        <mesh filename="package://sdh2_description/meshes/finger.stl"/>
      </geometry>
      <material name="Schunk/LightGrey"/>
    </visual>
    <collision>
      <origin rpy="0 0 0" xyz="0 0 0"/>
      <geometry>
        <mesh filename="package://sdh2_description/meshes/finger_low_res.stl"/>
      </geometry>
    </collision>
  </link>
  <joint name="sdh2_finger_23_joint" type="revolute">
    <origin rpy="0 0 0" xyz="0 0 0.0865"/>
    <parent link="sdh2_finger_22_link"/>
    <child link="sdh2_finger_23_link"/>
    <axis xyz="0 1 0"/>
    <dynamics damping="1"/>
    <limit effort="100" lower="-1.570796327" upper="1.570796327" velocity="5"/>
  </joint>
  <link name="sdh2_finger_23_link">
    <inertial>
      <origin rpy="0 0 0" xyz="0 0 0"/>
      <mass value="0.1"/>
      <inertia ixx="0.01" ixy="0" ixz="0" iyy="0.01" iyz="0" izz="0.01"/>
    </inertial>
    <visual>
      <origin rpy="0 0 0" xyz="0 0 0"/>
      <geometry>
        <mesh filename="package://sdh2_description/meshes/finger_tip.stl"/>
      </geometry>
      <material name="Schunk/LightGrey"/>
    </visual>
    <collision>
      <origin rpy="0 0 0" xyz="0 0 0"/>
      <geometry>
        <mesh filename="package://sdh2_description/meshes/finger_tip_low_res.stl"/>
      </geometry>
    </collision>
  </link>
  <joint name="sdh2_thumb_1_joint" type="fixed">
    <origin rpy="0 0 0" xyz="-0.03811 0 0.0745 "/>
    <parent link="sdh2_palm_link"/>
    <child link="sdh2_thumb_1_link"/>
  </joint>
  <link name="sdh2_thumb_1_link">
    <inertial>
      <origin rpy="0 0 0" xyz="0 0 0"/>
      <mass value="0.1"/>
      <inertia ixx="0.01" ixy="0" ixz="0" iyy="0.01" iyz="0" izz="0.01"/>
    </inertial>
    <visual>
      <origin rpy="0 0 0" xyz="0 0 0"/>
      <geometry>
        <mesh filename="package://sdh2_description/meshes/knuckle.stl"/>
      </geometry>
      <material name="Schunk/LightGrey"/>
    </visual>
    <collision>
      <origin rpy="0 0 0" xyz="0 0 0"/>
      <geometry>
        <mesh filename="package://sdh2_description/meshes/knuckle_low_res.stl"/>
      </geometry>
    </collision>
  </link>
  <joint name="sdh2_thumb_2_joint" type="revolute">
    <origin rpy="0 0 0" xyz="0 0 0.0165"/>
    <parent link="sdh2_thumb_1_link"/>
    <child link="sdh2_thumb_2_link"/>
    <axis xyz="0 1 0"/>
    <dynamics damping="1"/>
    <limit effort="100" lower="-1.570796327" upper="1.570796327" velocity="5"/>
  </joint>
  <link name="sdh2_thumb_2_link">
    <inertial>
      <origin rpy="0 0 0" xyz="0 0 0"/>
      <mass value="0.1"/>
      <inertia ixx="0.01" ixy="0" ixz="0" iyy="0.01" iyz="0" izz="0.01"/>
    </inertial>
    <visual>
      <origin rpy="0 0 0" xyz="0 0 0"/>
      <geometry>
        <mesh filename="package://sdh2_description/meshes/finger.stl"/>
      </geometry>
      <material name="Schunk/LightGrey"/>
    </visual>
    <collision>
      <origin rpy="0 0 0" xyz="0 0 0"/>
      <geometry>
        <mesh filename="package://sdh2_description/meshes/finger_low_res.stl"/>
      </geometry>
    </collision>
  </link>
  <joint name="sdh2_thumb_3_joint" type="revolute">
    <origin rpy="0 0 0" xyz="0 0 0.0865"/>
    <parent link="sdh2_thumb_2_link"/>
    <child link="sdh2_thumb_3_link"/>
    <axis xyz="0 1 0"/>
    <dynamics damping="1"/>
    <limit effort="100" lower="-1.570796327" upper="1.570796327" velocity="5"/>
  </joint>
  <link name="sdh2_thumb_3_link">
    <inertial>
      <origin rpy="0 0 0" xyz="0 0 0"/>
      <mass value="0.1"/>
      <inertia ixx="0.01" ixy="0" ixz="0" iyy="0.01" iyz="0" izz="0.01"/>
    </inertial>
    <visual>
      <origin rpy="0 0 0" xyz="0 0 0"/>
      <geometry>
        <mesh filename="package://sdh2_description/meshes/finger_tip.stl"/>
      </geometry>
      <material name="Schunk/LightGrey"/>
    </visual>
    <collision>
      <origin rpy="0 0 0" xyz="0 0 0"/>
      <geometry>
        <mesh filename="package://sdh2_description/meshes/finger_tip_low_res.stl"/>
      </geometry>
    </collision>
  </link>
  <gazebo reference="sdh2_palm_link">
    <material>Schunk/LightGrey</material>
    <turnGravityOff>false</turnGravityOff>
  </gazebo>
  <gazebo reference="sdh2_finger_11_link">
    <material>Schunk/LightGrey</material>
    <turnGravityOff>false</turnGravityOff>
  </gazebo>
  <gazebo reference="sdh2_finger_12_link">
    <selfCollide>true</selfCollide>
    <sensor:contact name="sdh2_finger_12_contact_sensor">
      <geom>sdh2_finger_12_link_geom</geom>
      <updateRate>100.0</updateRate>
      <controller:gazebo_ros_bumper name="sdh2_finger_12_gazebo_ros_bumper_controller" plugin="libgazebo_ros_bumper.so">
        <alwaysOn>true</alwaysOn>
        <updateRate>100.0</updateRate>
        <frameName>sdh2_finger_12_link</frameName>
        <bumperTopicName>sdh2_finger_12_bumper</bumperTopicName>
        <interface:bumper name="sdh2_finger_12_bumper_iface"/>
      </controller:gazebo_ros_bumper>
    </sensor:contact>
    <material>Schunk/LightGrey</material>
    <turnGravityOff>false</turnGravityOff>
  </gazebo>
  <gazebo reference="sdh2_finger_13_link">
    <selfCollide>true</selfCollide>
    <sensor:contact name="sdh2_finger_13_contact_sensor">
      <geom>sdh2_finger_13_link_geom</geom>
      <updateRate>100.0</updateRate>
      <controller:gazebo_ros_bumper name="sdh2_finger_13_gazebo_ros_bumper_controller" plugin="libgazebo_ros_bumper.so">
        <alwaysOn>true</alwaysOn>
        <updateRate>100.0</updateRate>
        <frameName>sdh2_finger_13_link</frameName>
        <bumperTopicName>sdh2_finger_13_bumper</bumperTopicName>
        <interface:bumper name="sdh2_finger_13_bumper_iface"/>
      </controller:gazebo_ros_bumper>
    </sensor:contact>
    <material>Schunk/LightGrey</material>
  </gazebo>
  <gazebo reference="sdh2_finger_21_link">
    <material>Schunk/LightGrey</material>
    <turnGravityOff>false</turnGravityOff>
  </gazebo>
  <gazebo reference="sdh2_finger_22_link">
    <selfCollide>true</selfCollide>
    <sensor:contact name="sdh2_finger_22_contact_sensor">
      <geom>sdh2_finger_22_link_geom</geom>
      <updateRate>100.0</updateRate>
      <controller:gazebo_ros_bumper name="sdh2_finger_22_gazebo_ros_bumper_controller" plugin="libgazebo_ros_bumper.so">
        <alwaysOn>true</alwaysOn>
        <updateRate>100.0</updateRate>
        <frameName>sdh2_finger_22_link</frameName>
        <bumperTopicName>sdh2_finger_22_bumper</bumperTopicName>
        <interface:bumper name="sdh2_finger_22_bumper_iface"/>
      </controller:gazebo_ros_bumper>
    </sensor:contact>
    <material>Schunk/LightGrey</material>
    <turnGravityOff>false</turnGravityOff>
  </gazebo>
  <gazebo reference="sdh2_finger_23_link">
    <selfCollide>true</selfCollide>
    <sensor:contact name="sdh2_finger_23_contact_sensor">
      <geom>sdh2_finger_23_link_geom</geom>
      <updateRate>100.0</updateRate>
      <controller:gazebo_ros_bumper name="sdh2_finger_23_gazebo_ros_bumper_controller" plugin="libgazebo_ros_bumper.so">
        <alwaysOn>true</alwaysOn>
        <updateRate>100.0</updateRate>
        <frameName>sdh2_finger_23_link</frameName>
        <bumperTopicName>sdh2_finger_23_bumper</bumperTopicName>
        <interface:bumper name="sdh2_finger_23_bumper_iface"/>
      </controller:gazebo_ros_bumper>
    </sensor:contact>
    <material>Schunk/LightGrey</material>
  </gazebo>
  <gazebo reference="sdh2_thumb_1_link">
    <material>Schunk/LightGrey</material>
    <turnGravityOff>false</turnGravityOff>
  </gazebo>
  <gazebo reference="sdh2_thumb_2_link">
    <selfCollide>true</selfCollide>
    <sensor:contact name="sdh2_thumb_2_contact_sensor">
      <geom>sdh2_thumb_2_link_geom</geom>
      <updateRate>100.0</updateRate>
      <controller:gazebo_ros_bumper name="sdh2_thumb_2_gazebo_ros_bumper_controller" plugin="libgazebo_ros_bumper.so">
        <alwaysOn>true</alwaysOn>
        <updateRate>100.0</updateRate>
        <frameName>sdh2_thumb_2_link</frameName>
        <bumperTopicName>sdh2_thumb_2_bumper</bumperTopicName>
        <interface:bumper name="sdh2_thumb_2_bumper_iface"/>
      </controller:gazebo_ros_bumper>
    </sensor:contact>
    <material>Schunk/LightGrey</material>
    <turnGravityOff>false</turnGravityOff>
  </gazebo>
  <gazebo reference="sdh2_thumb_3_link">
    <selfCollide>true</selfCollide>
    <sensor:contact name="sdh2_thumb_3_contact_sensor">
      <geom>sdh2_thumb_3_link_geom</geom>
      <updateRate>100.0</updateRate>
      <controller:gazebo_ros_bumper name="sdh2_thumb_3_gazebo_ros_bumper_controller" plugin="libgazebo_ros_bumper.so">
        <alwaysOn>true</alwaysOn>
        <updateRate>100.0</updateRate>
        <frameName>sdh2_thumb_3_link</frameName>
        <bumperTopicName>sdh2_thumb_3_bumper</bumperTopicName>
        <interface:bumper name="sdh2_thumb_3_bumper_iface"/>
      </controller:gazebo_ros_bumper>
    </sensor:contact>
    <material>Schunk/LightGrey</material>
  </gazebo>
  <transmission name="sdh2_knuckle_trans" type="pr2_mechanism_model/SimpleTransmission">
    <actuator name="sdh2_knuckle_motor"/>
    <joint name="sdh2_finger_21_joint"/>
    <mechanicalReduction>1</mechanicalReduction>
  </transmission>
  <transmission name="sdh2_knuckle_trans" type="pr2_mechanism_model/SimpleTransmission">
    <actuator name="sdh2_knuckle_motor"/>
    <joint name="sdh2_knuckle_joint"/>
    <mechanicalReduction>1</mechanicalReduction>
  </transmission>
  <transmission name="sdh2_finger_12_trans" type="pr2_mechanism_model/SimpleTransmission">
    <actuator name="sdh2_finger_12_motor"/>
    <joint name="sdh2_finger_12_joint"/>
    <mechanicalReduction>1</mechanicalReduction>
  </transmission>
  <transmission name="sdh2_finger_13_trans" type="pr2_mechanism_model/SimpleTransmission">
    <actuator name="sdh2_finger_13_motor"/>
    <joint name="sdh2_finger_13_joint"/>
    <mechanicalReduction>1</mechanicalReduction>
  </transmission>
  <transmission name="sdh2_finger_22_trans" type="pr2_mechanism_model/SimpleTransmission">
    <actuator name="sdh2_finger_22_motor"/>
    <joint name="sdh2_finger_22_joint"/>
    <mechanicalReduction>1</mechanicalReduction>
  </transmission>
  <transmission name="sdh2_finger_23_trans" type="pr2_mechanism_model/SimpleTransmission">
    <actuator name="sdh2_finger_23_motor"/>
    <joint name="sdh2_finger_23_joint"/>
    <mechanicalReduction>1</mechanicalReduction>
  </transmission>
  <transmission name="sdh2_thumb_2_trans" type="pr2_mechanism_model/SimpleTransmission">
    <actuator name="sdh2_thumb_2_motor"/>
    <joint name="sdh2_thumb_2_joint"/>
    <mechanicalReduction>1</mechanicalReduction>
  </transmission>
  <transmission name="sdh2_thumb_3_trans" type="pr2_mechanism_model/SimpleTransmission">
    <actuator name="sdh2_thumb_3_motor"/>
    <joint name="sdh2_thumb_3_joint"/>
    <mechanicalReduction>1</mechanicalReduction>
  </transmission>
</robot>
