<?xml version="1.0" ?>
<!-- =================================================================================== -->
<!-- |    This document was autogenerated by xacro from xacro/iiwa_sdh2.xacro          | -->
<!-- |    EDITING THIS FILE BY HAND IS NOT RECOMMENDED                                 | -->
<!-- =================================================================================== -->
<robot name="iiwa" xmlns:controller="http://playerstage.sourceforge.net/gazebo/xmlschema/#controller" xmlns:interface="http://playerstage.sourceforge.net/gazebo/xmlschema/#interface" xmlns:sensor="http://playerstage.sourceforge.net/gazebo/xmlschema/#sensor" xmlns:xacro="http://www.ros.org/wiki/xacro">
  <material name="Black">
    <color rgba="0.0 0.0 0.0 1.0"/>
  </material>
  <material name="Blue">
    <color rgba="0.0 0.0 0.8 1.0"/>
  </material>
  <material name="Green">
    <color rgba="0.0 0.8 0.0 1.0"/>
  </material>
  <material name="Grey">
    <color rgba="0.2 0.2 0.2 1.0"/>
  </material>
  <material name="Orange">
    <color rgba="1.0 0.423529411765 0.0392156862745 1.0"/>
  </material>
  <material name="Brown">
    <color rgba="0.870588235294 0.811764705882 0.764705882353 1.0"/>
  </material>
  <material name="Red">
    <color rgba="0.8 0.0 0.0 1.0"/>
  </material>
  <material name="White">
    <color rgba="1.0 1.0 1.0 1.0"/>
  </material>
  <gazebo>
    <plugin filename="libgazebo_ros_control.so" name="gazebo_ros_controller">
      <robotNamespace>/iiwa</robotNamespace>
    </plugin>
  </gazebo>
  <!-- Fix to world just for testing -->
  <link name="iiwa_base_link"/>
  <!--joint between {parent} and link_0-->
  <joint name="iiwa_base_link_joint" type="fixed">
    <origin rpy="0 0 0" xyz="0 0 0.0"/>
    <parent link="iiwa_base_link"/>
    <child link="iiwa_0_link"/>
  </joint>
  <link name="iiwa_0_link">
    <inertial>
      <origin rpy="0 0 0" xyz="-0.1 0 0.07"/>
      <mass value="5"/>
      <inertia ixx="0.05" ixy="0" ixz="0" iyy="0.06" iyz="0" izz="0.03"/>
    </inertial>
    <visual>
      <origin rpy="0 0 0" xyz="0 0 0"/>
      <geometry>
        <mesh filename="package://iiwa_description/meshes/link_0.stl"/>
      </geometry>
      <material name="Grey"/>
    </visual>
    <collision>
      <origin rpy="0 0 0" xyz="0 0 0"/>
      <geometry>
        <mesh filename="package://iiwa_description/meshes/coarse/link_0.stl"/>
      </geometry>
      <material name="Grey"/>
    </collision>
    <self_collision_checking>
      <origin rpy="0 0 0" xyz="0 0 0"/>
      <geometry>
        <capsule length="0.25" radius="0.15"/>
      </geometry>
    </self_collision_checking>
  </link>
  <!-- joint between link_0 and link_1 -->
  <joint name="iiwa_1_joint" type="revolute">
    <parent link="iiwa_0_link"/>
    <child link="iiwa_1_link"/>
    <origin rpy="0 0 0" xyz="0 0 0.1575"/>
    <axis xyz="0 0 1"/>
    <limit effort="300" lower="-2.94960643587" upper="2.94960643587" velocity="10"/>
    <!--   <safety_controller soft_lower_limit="${-168 * M_PI / 180}"
           soft_upper_limit="${168 * M_PI / 180}"
           k_position="${safety_controller_k_pos}"
           k_velocity="${safety_controller_k_vel}"/> -->
    <dynamics damping="0.5"/>
  </joint>
  <link name="iiwa_1_link">
    <inertial>
      <origin rpy="0 0 0" xyz="0 -0.03 0.12"/>
      <mass value="4"/>
      <inertia ixx="0.1" ixy="0" ixz="0" iyy="0.09" iyz="0" izz="0.02"/>
    </inertial>
    <visual>
      <origin rpy="0 0 0" xyz="0 0 0"/>
      <geometry>
        <mesh filename="package://iiwa_description/meshes/link_1.stl"/>
      </geometry>
      <material name="Orange"/>
    </visual>
    <collision>
      <origin rpy="0 0 0" xyz="0 0 0"/>
      <geometry>
        <mesh filename="package://iiwa_description/meshes/coarse/link_1.stl"/>
      </geometry>
      <material name="Orange"/>
    </collision>
  </link>
  <!-- joint between link_1 and link_2 -->
  <joint name="iiwa_2_joint" type="revolute">
    <parent link="iiwa_1_link"/>
    <child link="iiwa_2_link"/>
    <origin rpy="1.57079632679   0 3.14159265359" xyz="0 0 0.2025"/>
    <axis xyz="0 0 1"/>
    <limit effort="300" lower="-2.07694180987" upper="2.07694180987" velocity="10"/>
    <!-- <safety_controller soft_lower_limit="${-118 * PI / 180}"
           soft_upper_limit="${118 * PI / 180}"
           k_position="${safety_controller_k_pos}"
           k_velocity="${safety_controller_k_vel}"/> -->
    <dynamics damping="0.5"/>
  </joint>
  <link name="iiwa_2_link">
    <inertial>
      <origin rpy="0 0 0" xyz="0.0003 0.059 0.042"/>
      <mass value="4"/>
      <inertia ixx="0.05" ixy="0" ixz="0" iyy="0.018" iyz="0" izz="0.044"/>
    </inertial>
    <visual>
      <origin rpy="0 0 0" xyz="0 0 0"/>
      <geometry>
        <mesh filename="package://iiwa_description/meshes/link_2.stl"/>
      </geometry>
      <material name="Orange"/>
    </visual>
    <collision>
      <origin rpy="0 0 0" xyz="0 0 0"/>
      <geometry>
        <mesh filename="package://iiwa_description/meshes/coarse/link_2.stl"/>
      </geometry>
      <material name="Orange"/>
    </collision>
  </link>
  <!-- joint between link_2 and link_3 -->
  <joint name="iiwa_3_joint" type="revolute">
    <parent link="iiwa_2_link"/>
    <child link="iiwa_3_link"/>
    <origin rpy="1.57079632679 0 3.14159265359" xyz="0 0.2045 0"/>
    <axis xyz="0 0 1"/>
    <limit effort="300" lower="-2.94960643587" upper="2.94960643587" velocity="10"/>
    <!-- <safety_controller soft_lower_limit="${-118 * PI / 180}"
           soft_upper_limit="${118 * PI / 180}"
           k_position="${safety_controller_k_pos}"
           k_velocity="${safety_controller_k_vel}"/> -->
    <dynamics damping="0.5"/>
  </joint>
  <link name="iiwa_3_link">
    <inertial>
      <origin rpy="0 0 0" xyz="0 0.03 0.13"/>
      <mass value="3"/>
      <inertia ixx="0.08" ixy="0" ixz="0" iyy="0.075" iyz="0" izz="0.01"/>
    </inertial>
    <visual>
      <origin rpy="0 0 0" xyz="0 0 0"/>
      <geometry>
        <mesh filename="package://iiwa_description/meshes/link_3.stl"/>
      </geometry>
      <material name="Orange"/>
    </visual>
    <collision>
      <origin rpy="0 0 0" xyz="0 0 0"/>
      <geometry>
        <mesh filename="package://iiwa_description/meshes/coarse/link_3.stl"/>
      </geometry>
      <material name="Orange"/>
    </collision>
  </link>
  <!-- joint between link_3 and link_4 -->
  <joint name="iiwa_4_joint" type="revolute">
    <parent link="iiwa_3_link"/>
    <child link="iiwa_4_link"/>
    <origin rpy="1.57079632679 0 0" xyz="0 0 0.2155"/>
    <axis xyz="0 0 1"/>
    <limit effort="300" lower="-2.07694180987" upper="2.07694180987" velocity="10"/>
    <!-- <safety_controller soft_lower_limit="${-118 * PI / 180}"
           soft_upper_limit="${118 * PI / 180}"
           k_position="${safety_controller_k_pos}"
           k_velocity="${safety_controller_k_vel}"/> -->
    <dynamics damping="0.5"/>
  </joint>
  <link name="iiwa_4_link">
    <inertial>
      <origin rpy="0 0 0" xyz="0 0.067 0.034"/>
      <mass value="2.7"/>
      <inertia ixx="0.03" ixy="0" ixz="0" iyy="0.01" iyz="0" izz="0.029"/>
    </inertial>
    <visual>
      <origin rpy="0 0 0" xyz="0 0 0"/>
      <geometry>
        <mesh filename="package://iiwa_description/meshes/link_4.stl"/>
      </geometry>
      <material name="Orange"/>
    </visual>
    <collision>
      <origin rpy="0 0 0" xyz="0 0 0"/>
      <geometry>
        <mesh filename="package://iiwa_description/meshes/coarse/link_4.stl"/>
      </geometry>
      <material name="Orange"/>
    </collision>
  </link>
  <!-- joint between link_4 and link_5 -->
  <joint name="iiwa_5_joint" type="revolute">
    <parent link="iiwa_4_link"/>
    <child link="iiwa_5_link"/>
    <origin rpy="-1.57079632679 3.14159265359 0" xyz="0 0.1845 0"/>
    <axis xyz="0 0 1"/>
    <limit effort="300" lower="-2.94960643587" upper="2.94960643587" velocity="10"/>
    <!-- <safety_controller soft_lower_limit="${-118 * PI / 180}"
           soft_upper_limit="${118 * PI / 180}"
           k_position="${safety_controller_k_pos}"
           k_velocity="${safety_controller_k_vel}"/> -->
    <dynamics damping="0.5"/>
  </joint>
  <link name="iiwa_5_link">
    <inertial>
      <origin rpy="0 0 0" xyz="0.0001 0.021 0.076"/>
      <mass value="1.7"/>
      <inertia ixx="0.02" ixy="0" ixz="0" iyy="0.018" iyz="0" izz="0.005"/>
    </inertial>
    <visual>
      <origin rpy="0 0 0" xyz="0 0 0"/>
      <geometry>
        <mesh filename="package://iiwa_description/meshes/link_5.stl"/>
      </geometry>
      <material name="Orange"/>
    </visual>
    <collision>
      <origin rpy="0 0 0" xyz="0 0 0"/>
      <geometry>
        <mesh filename="package://iiwa_description/meshes/coarse/link_5.stl"/>
      </geometry>
      <material name="Orange"/>
    </collision>
  </link>
  <!-- joint between link_5 and link_6 -->
  <joint name="iiwa_6_joint" type="revolute">
    <parent link="iiwa_5_link"/>
    <child link="iiwa_6_link"/>
    <origin rpy="1.57079632679 0 0" xyz="0 0 0.2155"/>
    <axis xyz="0 0 1"/>
    <limit effort="300" lower="-2.07694180987" upper="2.07694180987" velocity="10"/>
    <!-- <safety_controller soft_lower_limit="${-118 * PI / 180}"
           soft_upper_limit="${118 * PI / 180}"
           k_position="${safety_controller_k_pos}"
           k_velocity="${safety_controller_k_vel}"/> -->
    <dynamics damping="0.5"/>
  </joint>
  <link name="iiwa_6_link">
    <inertial>
      <origin rpy="0 0 0" xyz="0 0.0006 0.0004"/>
      <mass value="1.8"/>
      <inertia ixx="0.005" ixy="0" ixz="0" iyy="0.0036" iyz="0" izz="0.0047"/>
    </inertial>
    <visual>
      <origin rpy="0 0 0" xyz="0 0 0"/>
      <geometry>
        <mesh filename="package://iiwa_description/meshes/link_6.stl"/>
      </geometry>
      <material name="Orange"/>
    </visual>
    <collision>
      <origin rpy="0 0 0" xyz="0 0 0"/>
      <geometry>
        <mesh filename="package://iiwa_description/meshes/coarse/link_6.stl"/>
      </geometry>
      <material name="Orange"/>
    </collision>
  </link>
  <!-- joint between link_6 and link_7 -->
  <joint name="iiwa_7_joint" type="revolute">
    <parent link="iiwa_6_link"/>
    <child link="iiwa_7_link"/>
    <origin rpy="-1.57079632679 3.14159265359 0" xyz="0 0.081 0"/>
    <axis xyz="0 0 1"/>
    <limit effort="300" lower="-3.03687289847" upper="3.03687289847" velocity="10"/>
    <!-- <safety_controller soft_lower_limit="${-118 * PI / 180}"
           soft_upper_limit="${118 * PI / 180}"
           k_position="${safety_controller_k_pos}"
           k_velocity="${safety_controller_k_vel}"/> -->
    <dynamics damping="0.5"/>
  </joint>
  <link name="iiwa_7_link">
    <inertial>
      <origin rpy="0 0 0" xyz="0 0 0.02"/>
      <mass value="0.3"/>
      <inertia ixx="0.001" ixy="0" ixz="0" iyy="0.001" iyz="0" izz="0.001"/>
    </inertial>
    <visual>
      <origin rpy="0 0 0" xyz="0 0 0"/>
      <geometry>
        <mesh filename="package://iiwa_description/meshes/link_7.stl"/>
      </geometry>
      <material name="Grey"/>
    </visual>
    <collision>
      <origin rpy="0 0 0" xyz="0 0 0"/>
      <geometry>
        <mesh filename="package://iiwa_description/meshes/coarse/link_7.stl"/>
      </geometry>
      <material name="Grey"/>
    </collision>
  </link>
  <joint name="adapter" type="fixed">
    <parent link="iiwa_7_link"/>
    <child link="iiwa_adapter"/>
    <origin rpy="0 0 0" xyz="0 0 0.06"/>
  </joint>
  <link name="iiwa_adapter">
    <visual>
      <geometry>
        <cylinder length="0.029" radius="0.039"/>
      </geometry>
      <material name="Grey"/>
    </visual>
    <collision>
      <geometry>
        <cylinder length="0.029" radius="0.039"/>
      </geometry>
    </collision>
  </link>
  <joint name="flange" type="fixed">
    <parent link="iiwa_adapter"/>
    <child link="iiwa_flange_link"/>
    <origin rpy="0 0 0" xyz="0 0 0.013"/>
  </joint>
  <link name="iiwa_flange_link"/>
  <!--Extensions -->
  <!-- <xacro:iiwa_gazebo name="${name}" />
    <xacro:iiwa_transmission name="${name}" hardware_interface="${hardware_interface}"/> -->
  <material name="Schunk/LightGrey">
    <color rgba="0.7 0.7 0.7 1.0"/>
  </material>
  <material name="Schunk/DarkGrey">
    <color rgba="0.4 0.4 0.4 1.0"/>
  </material>
  <material name="Schunk/Black">
    <color rgba="0.0 0.0 0.0 1.0"/>
  </material>
  <material name="Schunk/DarkGolden">
    <color rgba="0.4 0.4 0.3 1.0"/>
  </material>
  <material name="Schunk/Blue">
    <color rgba="0.0 0.0 0.8 1.0"/>
  </material>
  <link name="sdh2_adapter_link">
    <visual>
      <geometry>
        <cylinder length="0.028" radius="0.055"/>
      </geometry>
      <origin rpy="0 0 0" xyz="0 0 0.014"/>
      <material name="Grey"/>
    </visual>
    <collision>
      <geometry>
        <cylinder length="0.028" radius="0.055"/>
      </geometry>
      <origin rpy="0 0 0" xyz="0 0 0.014"/>
    </collision>
  </link>
  <!-- adapter joint -->
  <joint name="sdh2_adapter_joint" type="fixed">
    <origin rpy="0 0 0" xyz="0 0 0.028"/>
    <parent link="sdh2_adapter_link"/>
    <child link="sdh2_palm_link"/>
  </joint>
  <link name="sdh2_palm_link">
    <inertial>
      <origin rpy="0 0 0" xyz="0 0 0"/>
      <mass value="1"/>
      <inertia ixx="0.01" ixy="0" ixz="0" iyy="0.01" iyz="0" izz="0.01"/>
    </inertial>
    <visual>
      <origin rpy="0 0 0" xyz="0 0 0"/>
      <geometry>
        <mesh filename="package://sdh2_description/meshes/palm.stl"/>
      </geometry>
      <material name="Schunk/LightGrey"/>
    </visual>
    <collision>
      <origin rpy="0 0 0" xyz="0 0 0"/>
      <geometry>
        <mesh filename="package://sdh2_description/meshes/palm_low_res.stl"/>
      </geometry>
    </collision>
  </link>
  <!-- grasp joint -->
  <joint name="sdh2_grasp_joint" type="fixed">
    <origin rpy="0 0 0" xyz="-0.012 0 0.15"/>
    <parent link="sdh2_palm_link"/>
    <child link="sdh2_grasp_link"/>
  </joint>
  <link name="sdh2_grasp_link"/>
  <!-- tip joint -->
  <joint name="sdh2_tip_joint" type="fixed">
    <origin rpy="0 0 0" xyz="-0.012 0 0.22"/>
    <parent link="sdh2_palm_link"/>
    <child link="sdh2_tip_link"/>
  </joint>
  <link name="sdh2_tip_link"/>
  <!-- push joint -->
  <joint name="sdh2_push_joint" type="fixed">
    <origin rpy="0 0 0" xyz="0 0 0.25"/>
    <parent link="sdh2_palm_link"/>
    <child link="sdh2_push_link"/>
  </joint>
  <link name="sdh2_push_link"/>
  <!-- finger1 -->
  <!-- joint between sdh_palm_link and sdh_finger_11_link -->
  <joint name="sdh2_knuckle_joint" type="revolute">
    <origin rpy="0 0 3.14159265" xyz="0.01905 0.033 0.0745"/>
    <parent link="sdh2_palm_link"/>
    <child link="sdh2_finger_11_link"/>
    <axis xyz="0 0 1"/>
    <dynamics damping="1"/>
    <limit effort="100" lower="0" upper="1.570796327" velocity="5"/>
  </joint>
  <link name="sdh2_finger_11_link">
    <inertial>
      <origin rpy="0 0 0" xyz="0 0 0"/>
      <mass value="0.1"/>
      <inertia ixx="0.01" ixy="0" ixz="0" iyy="0.01" iyz="0" izz="0.01"/>
    </inertial>
    <visual>
      <origin rpy="0 0 0" xyz="0 0 0"/>
      <geometry>
        <mesh filename="package://sdh2_description/meshes/knuckle.stl"/>
      </geometry>
      <material name="Schunk/LightGrey"/>
    </visual>
    <collision>
      <origin rpy="0 0 0" xyz="0 0 0"/>
      <geometry>
        <mesh filename="package://sdh2_description/meshes/knuckle_low_res.stl"/>
      </geometry>
    </collision>
  </link>
  <!-- joint between sdh_finger_11_link and sdh_finger_12_link -->
  <joint name="sdh2_finger_12_joint" type="revolute">
    <origin rpy="0 0 0" xyz="0 0 0.0165"/>
    <parent link="sdh2_finger_11_link"/>
    <child link="sdh2_finger_12_link"/>
    <axis xyz="0 1 0"/>
    <dynamics damping="1"/>
    <limit effort="100" lower="-1.570796327" upper="1.570796327" velocity="5"/>
  </joint>
  <link name="sdh2_finger_12_link">
    <inertial>
      <origin rpy="0 0 0" xyz="0 0 0"/>
      <mass value="0.1"/>
      <inertia ixx="0.01" ixy="0" ixz="0" iyy="0.01" iyz="0" izz="0.01"/>
    </inertial>
    <visual>
      <origin rpy="0 0 0" xyz="0 0 0"/>
      <geometry>
        <mesh filename="package://sdh2_description/meshes/finger.stl"/>
      </geometry>
      <material name="Schunk/LightGrey"/>
    </visual>
    <collision>
      <origin rpy="0 0 0" xyz="0 0 0"/>
      <geometry>
        <mesh filename="package://sdh2_description/meshes/finger_low_res.stl"/>
      </geometry>
    </collision>
  </link>
  <!-- joint between sdh_finger_12_link and sdh_finger_13_link -->
  <joint name="sdh2_finger_13_joint" type="revolute">
    <origin rpy="0 0 0" xyz="0 0 0.0865"/>
    <parent link="sdh2_finger_12_link"/>
    <child link="sdh2_finger_13_link"/>
    <axis xyz="0 1 0"/>
    <dynamics damping="1"/>
    <limit effort="100" lower="-1.570796327" upper="1.570796327" velocity="5"/>
  </joint>
  <link name="sdh2_finger_13_link">
    <inertial>
      <origin rpy="0 0 0" xyz="0 0 0"/>
      <mass value="0.1"/>
      <inertia ixx="0.01" ixy="0" ixz="0" iyy="0.01" iyz="0" izz="0.01"/>
    </inertial>
    <visual>
      <origin rpy="0 0 0" xyz="0 0 0"/>
      <geometry>
        <mesh filename="package://sdh2_description/meshes/finger_tip.stl"/>
      </geometry>
      <material name="Schunk/LightGrey"/>
    </visual>
    <collision>
      <origin rpy="0 0 0" xyz="0 0 0"/>
      <geometry>
        <mesh filename="package://sdh2_description/meshes/finger_tip_low_res.stl"/>
      </geometry>
    </collision>
  </link>
  <!-- finger2 -->
  <!-- joint between sdh_palm_link and sdh_finger_21_link -->
  <joint name="sdh2_finger_21_joint" type="revolute">
    <mimic joint="sdh2_knuckle_joint" multiplier="1" offset="0"/>
    <origin rpy="0 0 3.14159265" xyz="0.01905 -0.033 0.0745"/>
    <parent link="sdh2_palm_link"/>
    <child link="sdh2_finger_21_link"/>
    <axis xyz="0 0 -1"/>
    <dynamics damping="1"/>
    <limit effort="100" lower="0" upper="1.570796327" velocity="5"/>
  </joint>
  <link name="sdh2_finger_21_link">
    <inertial>
      <origin rpy="0 0 0" xyz="0 0 0"/>
      <mass value="0.1"/>
      <inertia ixx="0.01" ixy="0" ixz="0" iyy="0.01" iyz="0" izz="0.01"/>
    </inertial>
    <visual>
      <origin rpy="0 0 0" xyz="0 0 0"/>
      <geometry>
        <mesh filename="package://sdh2_description/meshes/knuckle.stl"/>
      </geometry>
      <material name="Schunk/LightGrey"/>
    </visual>
    <collision>
      <origin rpy="0 0 0" xyz="0 0 0"/>
      <geometry>
        <mesh filename="package://sdh2_description/meshes/knuckle_low_res.stl"/>
      </geometry>
    </collision>
  </link>
  <!-- joint between sdh_finger_21_link and sdh_finger_22_link -->
  <joint name="sdh2_finger_22_joint" type="revolute">
    <origin rpy="0 0 0" xyz="0 0 0.0165"/>
    <parent link="sdh2_finger_21_link"/>
    <child link="sdh2_finger_22_link"/>
    <axis xyz="0 1 0"/>
    <dynamics damping="1"/>
    <limit effort="100" lower="-1.570796327" upper="1.570796327" velocity="5"/>
  </joint>
  <link name="sdh2_finger_22_link">
    <inertial>
      <origin rpy="0 0 0" xyz="0 0 0"/>
      <mass value="0.1"/>
      <inertia ixx="0.01" ixy="0" ixz="0" iyy="0.01" iyz="0" izz="0.01"/>
    </inertial>
    <visual>
      <origin rpy="0 0 0" xyz="0 0 0"/>
      <geometry>
        <mesh filename="package://sdh2_description/meshes/finger.stl"/>
      </geometry>
      <material name="Schunk/LightGrey"/>
    </visual>
    <collision>
      <origin rpy="0 0 0" xyz="0 0 0"/>
      <geometry>
        <mesh filename="package://sdh2_description/meshes/finger_low_res.stl"/>
      </geometry>
    </collision>
  </link>
  <!-- joint between sdh_finger_22_link and sdh_finger_23_link -->
  <joint name="sdh2_finger_23_joint" type="revolute">
    <origin rpy="0 0 0" xyz="0 0 0.0865"/>
    <parent link="sdh2_finger_22_link"/>
    <child link="sdh2_finger_23_link"/>
    <axis xyz="0 1 0"/>
    <dynamics damping="1"/>
    <limit effort="100" lower="-1.570796327" upper="1.570796327" velocity="5"/>
  </joint>
  <link name="sdh2_finger_23_link">
    <inertial>
      <origin rpy="0 0 0" xyz="0 0 0"/>
      <mass value="0.1"/>
      <inertia ixx="0.01" ixy="0" ixz="0" iyy="0.01" iyz="0" izz="0.01"/>
    </inertial>
    <visual>
      <origin rpy="0 0 0" xyz="0 0 0"/>
      <geometry>
        <mesh filename="package://sdh2_description/meshes/finger_tip.stl"/>
      </geometry>
      <material name="Schunk/LightGrey"/>
    </visual>
    <collision>
      <origin rpy="0 0 0" xyz="0 0 0"/>
      <geometry>
        <mesh filename="package://sdh2_description/meshes/finger_tip_low_res.stl"/>
      </geometry>
    </collision>
  </link>
  <!-- thumb -->
  <!-- joint between sdh_palm_link and sdh_thumb_1_link -->
  <joint name="sdh2_thumb_1_joint" type="fixed">
    <origin rpy="0 0 0" xyz="-0.03811 0 0.0745 "/>
    <parent link="sdh2_palm_link"/>
    <child link="sdh2_thumb_1_link"/>
  </joint>
  <link name="sdh2_thumb_1_link">
    <inertial>
      <origin rpy="0 0 0" xyz="0 0 0"/>
      <mass value="0.1"/>
      <inertia ixx="0.01" ixy="0" ixz="0" iyy="0.01" iyz="0" izz="0.01"/>
    </inertial>
    <visual>
      <origin rpy="0 0 0" xyz="0 0 0"/>
      <geometry>
        <mesh filename="package://sdh2_description/meshes/knuckle.stl"/>
      </geometry>
      <material name="Schunk/LightGrey"/>
    </visual>
    <collision>
      <origin rpy="0 0 0" xyz="0 0 0"/>
      <geometry>
        <mesh filename="package://sdh2_description/meshes/knuckle_low_res.stl"/>
      </geometry>
    </collision>
  </link>
  <!-- joint between sdh_thumb_1_link and shd_thumb_2_link -->
  <joint name="sdh2_thumb_2_joint" type="revolute">
    <origin rpy="0 0 0" xyz="0 0 0.0165"/>
    <parent link="sdh2_thumb_1_link"/>
    <child link="sdh2_thumb_2_link"/>
    <axis xyz="0 1 0"/>
    <dynamics damping="1"/>
    <limit effort="100" lower="-1.570796327" upper="1.570796327" velocity="5"/>
  </joint>
  <link name="sdh2_thumb_2_link">
    <inertial>
      <origin rpy="0 0 0" xyz="0 0 0"/>
      <mass value="0.1"/>
      <inertia ixx="0.01" ixy="0" ixz="0" iyy="0.01" iyz="0" izz="0.01"/>
    </inertial>
    <visual>
      <origin rpy="0 0 0" xyz="0 0 0"/>
      <geometry>
        <mesh filename="package://sdh2_description/meshes/finger.stl"/>
      </geometry>
      <material name="Schunk/LightGrey"/>
    </visual>
    <collision>
      <origin rpy="0 0 0" xyz="0 0 0"/>
      <geometry>
        <mesh filename="package://sdh2_description/meshes/finger_low_res.stl"/>
      </geometry>
    </collision>
  </link>
  <!-- joint between sdh_thumb_2_link and sdh_thumb_3_link -->
  <joint name="sdh2_thumb_3_joint" type="revolute">
    <origin rpy="0 0 0" xyz="0 0 0.0865"/>
    <parent link="sdh2_thumb_2_link"/>
    <child link="sdh2_thumb_3_link"/>
    <axis xyz="0 1 0"/>
    <dynamics damping="1"/>
    <limit effort="100" lower="-1.570796327" upper="1.570796327" velocity="5"/>
  </joint>
  <link name="sdh2_thumb_3_link">
    <inertial>
      <origin rpy="0 0 0" xyz="0 0 0"/>
      <mass value="0.1"/>
      <inertia ixx="0.01" ixy="0" ixz="0" iyy="0.01" iyz="0" izz="0.01"/>
    </inertial>
    <visual>
      <origin rpy="0 0 0" xyz="0 0 0"/>
      <geometry>
        <mesh filename="package://sdh2_description/meshes/finger_tip.stl"/>
      </geometry>
      <material name="Schunk/LightGrey"/>
    </visual>
    <collision>
      <origin rpy="0 0 0" xyz="0 0 0"/>
      <geometry>
        <mesh filename="package://sdh2_description/meshes/finger_tip_low_res.stl"/>
      </geometry>
    </collision>
  </link>
  <!-- ros_control plugin -->
  <gazebo>
    <plugin filename="libgazebo_ros_control.so" name="gazebo_ros_control">
      <robotNamespace>/sdh2</robotNamespace>
      <robotSimType>gazebo_ros_control/DefaultRobotHWSim</robotSimType>
    </plugin>
  </gazebo>
  <gazebo reference="sdh2_adapter_link">
    <material>Schunk/LightGrey</material>
    <turnGravityOff>false</turnGravityOff>
  </gazebo>
  <gazebo reference="sdh2_palm_link">
    <material>Schunk/LightGrey</material>
    <turnGravityOff>false</turnGravityOff>
  </gazebo>
  <gazebo reference="sdh2_finger_11_link">
    <material>Schunk/LightGrey</material>
    <turnGravityOff>false</turnGravityOff>
  </gazebo>
  <gazebo reference="sdh2_finger_12_link">
    <selfCollide>true</selfCollide>
    <material>Schunk/LightGrey</material>
    <turnGravityOff>false</turnGravityOff>
  </gazebo>
  <gazebo reference="sdh2_finger_13_link">
    <selfCollide>true</selfCollide>
    <material>Schunk/LightGrey</material>
  </gazebo>
  <gazebo reference="sdh2_finger_21_link">
    <material>Schunk/LightGrey</material>
    <turnGravityOff>false</turnGravityOff>
  </gazebo>
  <gazebo reference="sdh2_finger_22_link">
    <selfCollide>true</selfCollide>
    <material>Schunk/LightGrey</material>
    <turnGravityOff>false</turnGravityOff>
  </gazebo>
  <gazebo reference="sdh2_finger_23_link">
    <selfCollide>true</selfCollide>
    <material>Schunk/LightGrey</material>
  </gazebo>
  <gazebo reference="sdh2_thumb_1_link">
    <material>Schunk/LightGrey</material>
    <turnGravityOff>false</turnGravityOff>
  </gazebo>
  <gazebo reference="sdh2_thumb_2_link">
    <selfCollide>true</selfCollide>
    <material>Schunk/LightGrey</material>
    <turnGravityOff>false</turnGravityOff>
  </gazebo>
  <gazebo reference="sdh2_thumb_3_link">
    <selfCollide>true</selfCollide>
    <material>Schunk/LightGrey</material>
  </gazebo>
  <transmission name="sdh2_knuckle_trans">
    <type>pr2_mechanism_model/SimpleTransmission</type>
    <actuator name="sdh2_knuckle_motor">
      <hardwareInterface>EffortJointInterface</hardwareInterface>
    </actuator>
    <joint name="sdh2_finger_21_joint">
      <hardwareInterface>EffortJointInterface</hardwareInterface>
    </joint>
    <mechanicalReduction>1</mechanicalReduction>
  </transmission>
  <transmission name="sdh2_knuckle_trans">
    <type>pr2_mechanism_model/SimpleTransmission</type>
    <actuator name="sdh2_knuckle_motor">
      <hardwareInterface>EffortJointInterface</hardwareInterface>
    </actuator>
    <joint name="sdh2_knuckle_joint">
      <hardwareInterface>EffortJointInterface</hardwareInterface>
    </joint>
    <mechanicalReduction>1</mechanicalReduction>
  </transmission>
  <!-- finger1 -->
  <transmission name="sdh2_finger_12_trans">
    <type>pr2_mechanism_model/SimpleTransmission</type>
    <actuator name="sdh2_finger_12_motor">
      <hardwareInterface>EffortJointInterface</hardwareInterface>
    </actuator>
    <joint name="sdh2_finger_12_joint">
      <hardwareInterface>EffortJointInterface</hardwareInterface>
    </joint>
    <mechanicalReduction>1</mechanicalReduction>
  </transmission>
  <transmission name="sdh2_finger_13_trans">
    <type>pr2_mechanism_model/SimpleTransmission</type>
    <actuator name="sdh2_finger_13_motor">
      <hardwareInterface>EffortJointInterface</hardwareInterface>
    </actuator>
    <joint name="sdh2_finger_13_joint">
      <hardwareInterface>EffortJointInterface</hardwareInterface>
    </joint>
    <mechanicalReduction>1</mechanicalReduction>
  </transmission>
  <!-- finger2 -->
  <transmission name="sdh2_finger_22_trans">
    <type>pr2_mechanism_model/SimpleTransmission</type>
    <actuator name="sdh2_finger_22_motor">
      <hardwareInterface>EffortJointInterface</hardwareInterface>
    </actuator>
    <joint name="sdh2_finger_22_joint">
      <hardwareInterface>EffortJointInterface</hardwareInterface>
    </joint>
    <mechanicalReduction>1</mechanicalReduction>
  </transmission>
  <transmission name="sdh2_finger_23_trans">
    <type>pr2_mechanism_model/SimpleTransmission</type>
    <actuator name="sdh2_finger_23_motor">
      <hardwareInterface>EffortJointInterface</hardwareInterface>
    </actuator>
    <joint name="sdh2_finger_23_joint">
      <hardwareInterface>EffortJointInterface</hardwareInterface>
    </joint>
    <mechanicalReduction>1</mechanicalReduction>
  </transmission>
  <!-- thumb -->
  <transmission name="sdh2_thumb_2_trans">
    <type>pr2_mechanism_model/SimpleTransmission</type>
    <actuator name="sdh2_thumb_2_motor">
      <hardwareInterface>EffortJointInterface</hardwareInterface>
    </actuator>
    <joint name="sdh2_thumb_2_joint">
      <hardwareInterface>EffortJointInterface</hardwareInterface>
    </joint>
    <mechanicalReduction>1</mechanicalReduction>
  </transmission>
  <transmission name="sdh2_thumb_3_trans">
    <type>pr2_mechanism_model/SimpleTransmission</type>
    <actuator name="sdh2_thumb_3_motor">
      <hardwareInterface>EffortJointInterface</hardwareInterface>
    </actuator>
    <joint name="sdh2_thumb_3_joint">
      <hardwareInterface>EffortJointInterface</hardwareInterface>
    </joint>
    <mechanicalReduction>1</mechanicalReduction>
  </transmission>
  <joint name="sdh2_palm_joint" type="fixed">
    <origin rpy="0 0 3.1415926535897931" xyz="0 0 0"/>
    <parent link="iiwa_flange_link"/>
    <child link="sdh2_adapter_link"/>
  </joint>
</robot>
