<?xml version="1.0"?>
<robot xmlns:xacro="http://www.ros.org/wiki/xacro">

	<xacro:macro name="wsg" params="name parent_link_name">

		<material name="lightGrey">
			<color rgba="0.7 0.7 0.7 1.0" />
		</material>


		<link name="${name}_gripper_tip_frame">
		</link>

		<link name="${name}_gripper_l_tip_frame">
			<visual>
				<geometry>
					<mesh filename="package://wsg_description/meshes/grip_low_res.stl" />
				</geometry>
				<material name="lightGrey" />
				<origin xyz="0 -0.0185 -0.040" rpy="-1.57 0 -1.57" />
			</visual>
			<collision>
				<origin xyz="0 -0.0185 -0.040" rpy="-1.57 0 -1.57" />
				<geometry>
					<mesh filename="package://wsg_description/meshes/grip_low_res.stl" />
				</geometry>
			</collision>
		</link>

		<link name="${name}_gripper_r_tip_frame">
			<visual>
				<geometry>
					<mesh filename="package://wsg_description/meshes/grip_low_res.stl" />
				</geometry>
				<material name="lightGrey" />
				<origin xyz="0 0.0185 -0.040" rpy="-1.57 0 1.57" />
			</visual>
			<collision>
				<origin xyz="0 0.0185 -0.040" rpy="-1.57 0 1.57" />
				<geometry>
					<mesh filename="package://wsg_description/meshes/grip_low_res.stl" />
				</geometry>
			</collision>
		</link>

		<link name="${name}_palm_frame">
			<visual>
				<geometry>
					<mesh filename="package://wsg_description/meshes/palm_low_res.stl" />
				</geometry>
				<material name="lightGrey" />
				<origin xyz="0 0 0.0725" />
			</visual>
			<collision>
				<geometry>
					<mesh filename="package://wsg_description/meshes/palm_collision.stl" />
				</geometry>
				<material name="lightGrey" />
				<origin xyz="0 0 0.0725" />
			</collision>
		</link>

		<!-- Connection to omnirob -->
		<joint name="${name}_gripper_palm" type="fixed">
			<!--parent link="lbr_flange_link" /-->
			<parent link="${parent_link_name}_flange_link" />
			<child link="${name}_palm_frame" />
			<!--insert_block name="origin"/ -->
			<!--origin xyz="0.0 0.0 0.0725" rpy="0 0 0"/ -->
			<!--origin xyz="0.0 0.005 0.171" rpy="0 0 0" / -->
			<origin rpy="0 0 -0.785398" xyz="0.0 0.0 0.0"/>
		</joint>

		<joint name="${name}_gripper_tip" type="fixed">
			<parent link="${name}_palm_frame" />
			<child link="${name}_gripper_tip_frame" />
			<origin xyz="0.0 0.0 0.1085" rpy="0 0 0" />
			<!--origin xyz="0.0 0.0 0.0721" rpy="1.57 0 0"/ -->
		</joint>

		<joint name="${name}_gripper_l_tip" type="prismatic">
			<parent link="${name}_palm_frame" />
			<child link="${name}_gripper_l_tip_frame" />
			<axis xyz="-1 0 0"/>
			<origin xyz="0 0 0.0725" rpy="0 0 0" />
			<limit lower="0.0" upper="0.07" effort="20" velocity="2.0"/>
			<!--<limit effort="1000.0" lower="0.0" upper="0.09" velocity="0.2"/> -->
		</joint>

		<joint name="${name}_gripper_r_tip" type="prismatic">
			<parent link="${name}_palm_frame" />
			<child link="${name}_gripper_r_tip_frame" />
			<axis xyz="1 0 0"/>
			<origin xyz="0 0 0.0725" rpy="0 0 0" />
			<limit lower="0.0" upper="0.07" effort="20" velocity="2.0"/>
			<!--<limit effort="1000.0" lower="0.0" upper="0.09" velocity="0.2"/> -->
		</joint>

	</xacro:macro>

</robot>
