<?xml version="1.0"?>
<!-- FROM: https://github.com/IDSCETHZurich/re_trajectory-generator -->
<robot xmlns:xacro="http://ros.org/wiki/xacro">

  
  <!-- Import all Gazebo-customization elements, including Gazebo colors -->
	<xacro:include filename="$(find omnirob_description)/urdf/xacro/lbr_only.gazebo" />
	<!-- Import Rviz colors -->
	<xacro:include filename="$(find omnirob_description)/urdf/xacro/lbr_materials.xacro" />
	

	<xacro:macro name="lbr_only" params="name">

		<!-- Used for fixing robot to Gazebo 'base_link' -->
		<!--<link name="world"/>
		
		<joint name="fixed" type="fixed">
		  <parent link="world"/>
		  <child link="${name}_0_link"/>
		</joint>-->
  
		<link name="${name}_0_link">
			<inertial>
				<origin xyz="0 0 0" rpy="0 0 0" />
				<mass value="1.0" />
				<inertia ixx="0.01" ixy="0" ixz="0" iyy="0.01" iyz="0" izz="0.01" />
			</inertial>

			<visual>
				<origin xyz="0 0 0" rpy="0 0 0" />
				<geometry>
					<mesh filename="package://omnirob_description/meshes/lbr0.stl" />
				</geometry>
				<material name="Blue" />
			</visual>

			<collision>
				<origin xyz="0 0 0" rpy="0 0 0" />
				<geometry>
					<mesh filename="package://omnirob_description/meshes/lbr0_low_res.stl" />
				</geometry>
			</collision>
		</link>

		<!-- joint between arm_0_link and arm_1_link -->
		<joint name="${name}_1_joint" type="revolute">
			<!--<origin xyz="0 0 0.14" rpy="0 0 -2.8407"/> -->
			<origin xyz="0 0 0.1105" rpy="0 0 0" />
			<parent link="${name}_0_link" />
			<child link="${name}_1_link" />
			<axis xyz="0 0 1" />
			<dynamics damping="25" />
			<limit effort="200" velocity="1.9634" lower="-2.9670" upper="2.9670" />
		</joint>

		<link name="${name}_1_link">
			<inertial>
				<origin xyz="0 0 0" rpy="0 0 0" />
				<mass value="5.9907" />
				<inertia ixx="0.01" ixy="0" ixz="0" iyy="0.01" iyz="0" izz="0.01" />
			</inertial>

			<visual>
				<origin xyz="0 0 0" rpy="0 0 0" />
				<geometry>
					<mesh filename="package://omnirob_description/meshes/lbr1.stl" />
				</geometry>
				<material name="Blue" />
			</visual>

			<collision>
				<origin xyz="0 0 0" rpy="0 0 0" />
				<geometry>
					<mesh filename="package://omnirob_description/meshes/lbr1_low_res.stl" />
				</geometry>
			</collision>
		</link>

		<!-- joint between arm_1_link and arm_2_link -->
		<joint name="${name}_2_joint" type="revolute">
			<origin xyz="0 0 0.1915" rpy="1.5708 0 0" />
			<parent link="${name}_1_link" />
			<child link="${name}_2_link" />
			<axis xyz="0 0 1" />
			<dynamics damping="25" />
			<limit effort="200" velocity="1.9634" lower="-2.0943" upper="2.0943" />
		</joint>

		<link name="${name}_2_link">
			<inertial>
				<origin xyz="0 0 0.002" rpy="0 0 0" />
				<mass value="5.734939" />
				<inertia ixx="0.03" ixy="0" ixz="0" iyy="0.03" iyz="0" izz="0.03" />
			</inertial>

			<visual>
				<origin xyz="0 0 0.002" rpy="0 0 0" />
				<geometry>
					<mesh filename="package://omnirob_description/meshes/lbr2.stl" />
				</geometry>
				<material name="Red" />
			</visual>

			<collision>
				<origin xyz="0 0 0.002" rpy="0 0 0" />
				<geometry>
					<mesh filename="package://omnirob_description/meshes/lbr2_low_res.stl" />
				</geometry>
			</collision>
		</link>

		<!-- joint between arm_2_link and arm_3_link -->
		<joint name="${name}_3_joint" type="revolute">
			<origin xyz="0 0.2085 0" rpy="-1.5708 0 0" />
			<parent link="${name}_2_link" />
			<child link="${name}_3_link" />
			<axis xyz="0 0 1" />
			<dynamics damping="25" />
			<limit effort="100" velocity="1.9634" lower="-2.9670" upper="2.9670" />
		</joint>

		<link name="${name}_3_link">
			<inertial>
				<origin xyz="0 -0.002 0" rpy="0 0 0" />
				<mass value="4.214668" />
				<inertia ixx="0.03" ixy="0" ixz="0" iyy="0.03" iyz="0" izz="0.03" />
			</inertial>

			<visual>
				<origin xyz="0 -0.002 0" rpy="0 0 0" />
				<geometry>
					<mesh filename="package://omnirob_description/meshes/lbr3.stl" />
				</geometry>
				<material name="Blue" />
			</visual>

			<collision>
				<origin xyz="0 -0.002 0" rpy="0 0 0" />
				<geometry>
					<mesh filename="package://omnirob_description/meshes/lbr3_low_res.stl" />
				</geometry>
			</collision>
		</link>

		<!-- joint between arm_3_link and arm_4_link -->
		<joint name="${name}_4_joint" type="revolute">
			<origin xyz="0 0 0.1915" rpy="-1.5708 0 0" />
			<parent link="${name}_3_link" />
			<child link="${name}_4_link" />
			<axis xyz="0 0 1" />
			<dynamics damping="25" />
			<limit effort="100" velocity="1.9634" lower="-2.0943" upper="2.0943" />
		</joint>

		<link name="${name}_4_link">
			<inertial>
				<origin xyz="0 0 0" rpy="0 0 0" />
				<mass value="3.669819" />
				<inertia ixx="0.03" ixy="0" ixz="0" iyy="0.03" iyz="0" izz="0.03" />
			</inertial>

			<visual>
				<origin xyz="0 0 0" rpy="0 0 0" />
				<geometry>
					<mesh filename="package://omnirob_description/meshes/lbr4.stl" />
				</geometry>
				<material name="Red" />
			</visual>

			<collision>
				<origin xyz="0 0 0" rpy="0 0 0" />
				<geometry>
					<mesh filename="package://omnirob_description/meshes/lbr4_low_res.stl" />
				</geometry>
			</collision>
		</link>

		<!-- joint between arm_4_link and arm_5_link -->
		<joint name="${name}_5_joint" type="revolute">
			<origin xyz="0 -0.2085 0" rpy="1.5708 0 0" />
			<parent link="${name}_4_link" />
			<child link="${name}_5_link" />
			<axis xyz="0 0 1" />
			<dynamics damping="25" />
			<limit effort="100" velocity="3.1415926" lower="-2.9670" upper="2.9670" />
		</joint>
		<link name="${name}_5_link">
			<inertial>
				<origin xyz="0 0 0" rpy="0 0 0" />
				<mass value="2.313272" />
				<inertia ixx="0.03" ixy="0" ixz="0" iyy="0.03" iyz="0" izz="0.03" />
			</inertial>

			<visual>
				<origin xyz="0 0 0" rpy="0 0 0" />
				<geometry>
					<mesh filename="package://omnirob_description/meshes/lbr5.stl" />
				</geometry>
				<material name="Blue" />
			</visual>

			<collision>
				<origin xyz="0 0 0" rpy="0 0 0" />
				<geometry>
					<mesh filename="package://omnirob_description/meshes/lbr5_low_res.stl" />
				</geometry>
			</collision>
		</link>

		<!-- joint between arm_5_link and arm_6_link -->
		<joint name="${name}_6_joint" type="revolute">
			<origin xyz="0 0 0.1815" rpy="1.5708 0 0" /> 
			<parent link="${name}_5_link" />
			<child link="${name}_6_link" />
			<axis xyz="0 0 1" />
			<dynamics damping="25" />
			<limit effort="30" velocity="1.9634" lower="-2.0943951" upper="2.0943951" />
		</joint>
		<link name="${name}_6_link">
			<inertial>
				<origin xyz="0 0 0" rpy="0 0 0" />
				<mass value="2.057856" />
				<inertia ixx="0.01" ixy="0" ixz="0" iyy="0.01" iyz="0" izz="0.01" />
			</inertial>

			<visual>
				<origin xyz="0 0 -0.046" rpy="0 0 0" />
				<geometry>
					<mesh filename="package://omnirob_description/meshes/lbr6.stl" />
				</geometry>
				<material name="Red" />
			</visual>

			<collision>
				<origin xyz="0 0 -0.046" rpy="0 0 0" />
				<geometry>
					<mesh filename="package://omnirob_description/meshes/lbr6_low_res.stl" />
				</geometry>
			</collision>
		</link>

		<!-- joint between arm_6_link and arm_7_link -->
		<joint name="${name}_7_joint" type="revolute">
			<origin xyz="0 0.057 0" rpy="-1.5708 0 0" />
			<parent link="${name}_6_link" />
			<child link="${name}_7_link" />
			<axis xyz="0 0 1" />
			<dynamics damping="25" />
			<limit effort="30" velocity="1.9634" lower="-2.9670" upper="2.9670" />
		</joint>
		<link name="${name}_7_link">
			<inertial>
				<origin xyz="0 0 0" rpy="0 0 0" />
				<mass value="1.120198" />
				<inertia ixx="0.01" ixy="0" ixz="0" iyy="0.01" iyz="0" izz="0.01" />
			</inertial>

			<visual>
				<origin xyz="0 0 0" rpy="0 0 0" />
				<geometry>
					<mesh filename="package://omnirob_description/meshes/lbr7.stl" />
				</geometry>
				<material name="Blue" />
			</visual>

			<collision>
				<origin xyz="0 0 0" rpy="0 0 0" />
				<geometry>
					<mesh filename="package://omnirob_description/meshes/lbr7_low_res.stl" />
				</geometry>
			</collision>
		</link>

		<joint name="flange" type="fixed">
    		<parent link="${name}_7_link"/>
   			<child link="${name}_flange_link"/>
    		<origin rpy="0 0 0" xyz="0 0 0.0195"/>
 		</joint>

		<link name="${name}_flange_link">
		</link>
		
		
		
		<transmission name="${name}_1_joint_trans">
			<type>pr2_mechanism_model/SimpleTransmission</type>
			<joint name="${name}_1_joint">
			  <hardwareInterface>EffortJointInterface</hardwareInterface>
			</joint>
			<actuator name="${name}_1_joint_motor">
			  <hardwareInterface>EffortJointInterface</hardwareInterface>
			  <mechanicalReduction>1</mechanicalReduction>
			</actuator>
		</transmission>
		
		
		<transmission name="${name}_2_joint_trans">
			<type>pr2_mechanism_model/SimpleTransmission</type>
			<joint name="${name}_2_joint">
			   <hardwareInterface>EffortJointInterface</hardwareInterface>
			</joint>
			<actuator name="${name}_2_joint_motor">
			  <hardwareInterface>EffortJointInterface</hardwareInterface>
			  <mechanicalReduction>1</mechanicalReduction>
			</actuator>
		</transmission>
		
		<transmission name="${name}_3_joint_trans">
			<type>pr2_mechanism_model/SimpleTransmission</type>
			<joint name="${name}_3_joint">
			   <hardwareInterface>EffortJointInterface</hardwareInterface>
			</joint>
			<actuator name="${name}_3_joint_motor">
			  <hardwareInterface>EffortJointInterface</hardwareInterface>
			  <mechanicalReduction>1</mechanicalReduction>
			</actuator>
		</transmission>
		
		
		<transmission name="${name}_4_joint_trans">
			<type>pr2_mechanism_model/SimpleTransmission</type>
			<joint name="${name}_4_joint">
			   <hardwareInterface>EffortJointInterface</hardwareInterface>
			</joint>
			<actuator name="${name}_4_joint_motor">
			  <hardwareInterface>EffortJointInterface</hardwareInterface>
			  <mechanicalReduction>1</mechanicalReduction>
			</actuator>
		</transmission>
		
		<transmission name="${name}_5_joint_trans">
			<type>pr2_mechanism_model/SimpleTransmission</type>
			<actuator name="${name}_5_joint_motor">
			  <hardwareInterface>EffortJointInterface</hardwareInterface>
			  <mechanicalReduction>1</mechanicalReduction>
			</actuator>
			<joint name="${name}_5_joint">
			   <hardwareInterface>EffortJointInterface</hardwareInterface>
			</joint>
		</transmission>
		
		
		<transmission name="${name}_6_joint_trans">
			<type>pr2_mechanism_model/SimpleTransmission</type>
			<actuator name="${name}_6_joint_motor">
			  <hardwareInterface>EffortJointInterface</hardwareInterface>
			  <mechanicalReduction>1</mechanicalReduction>
			</actuator>
			<joint name="${name}_6_joint">
			   <hardwareInterface>EffortJointInterface</hardwareInterface>
			</joint>
		</transmission>

		
		<transmission name="${name}_7_joint_trans">
			<type>pr2_mechanism_model/SimpleTransmission</type>
			<actuator name="${name}_7_joint_motor">
			  <hardwareInterface>EffortJointInterface</hardwareInterface>
			  <mechanicalReduction>1</mechanicalReduction>
			</actuator>
			<joint name="${name}_7_joint">
			   <hardwareInterface>EffortJointInterface</hardwareInterface>
			</joint>
		</transmission>
		

	</xacro:macro>

</robot>
