<?xml version="1.0" ?>
<!-- =================================================================================== -->
<!-- |    This document was autogenerated by xacro from lbr_sdh2.xacro                 | -->
<!-- |    EDITING THIS FILE BY HAND IS NOT RECOMMENDED                                 | -->
<!-- =================================================================================== -->
<robot name="lbr" xmlns:controller="http://playerstage.sourceforge.net/gazebo/xmlschema/#controller" xmlns:interface="http://playerstage.sourceforge.net/gazebo/xmlschema/#interface" xmlns:sensor="http://playerstage.sourceforge.net/gazebo/xmlschema/#sensor" xmlns:xacro="http://ros.org/wiki/xacro">
  
  
  <!-- ros_control plugin -->
  <gazebo>
    <plugin name="gazebo_ros_control" filename="libgazebo_ros_control.so">
      <robotNamespace>/lbr</robotNamespace>
      <robotSimType>gazebo_ros_control/DefaultRobotHWSim</robotSimType>
    </plugin>
  </gazebo>
  
  <material name="Blue">
    <color rgba="0.0 0.0 0.8 1.0"/>
  </material>
  <material name="Green">
    <color rgba="0.0 0.8 0.0 1.0"/>
  </material>
  <material name="Grey">
    <color rgba="0.7 0.7 0.7 1.0"/>
  </material>
  <material name="Grey2">
    <color rgba="0.9 0.9 0.9 1.0"/>
  </material>
  <material name="Red">
    <color rgba="0.8 0.0 0.0 1.0"/>
  </material>
  <material name="White">
    <color rgba="1.0 1.0 1.0 1.0"/>
  </material>
  <material name="Black">
    <color rgba="0.0 0.0 0.0 1.0"/>
  </material>
  <material name="Schunk/LightGrey">
    <color rgba="0.7 0.7 0.7 1.0"/>
  </material>
  <material name="Schunk/DarkGrey">
    <color rgba="0.4 0.4 0.4 1.0"/>
  </material>
  <material name="Schunk/Black">
    <color rgba="0.0 0.0 0.0 1.0"/>
  </material>
  <material name="Schunk/DarkGolden">
    <color rgba="0.4 0.4 0.3 1.0"/>
  </material>
  <material name="Schunk/Blue">
    <color rgba="0.0 0.0 0.8 1.0"/>
  </material>
  
  <link name="lbr_0_link">
    <inertial>
      <origin rpy="0 0 0" xyz="0 0 0"/>
      <mass value="1.0"/>
      <inertia ixx="0.01" ixy="0" ixz="0" iyy="0.01" iyz="0" izz="0.01"/>
    </inertial>
    <visual>
      <origin rpy="0 0 0" xyz="0 0 0"/>
      <geometry>
        <mesh filename="package://omnirob_description/meshes/lbr0.stl"/>
      </geometry>
      <material name="Blue"/>
    </visual>
    <collision>
      <origin rpy="0 0 0" xyz="0 0 0"/>
      <geometry>
        <mesh filename="package://omnirob_description/meshes/lbr0_low_res.stl"/>
      </geometry>
    </collision>
  </link>
  <joint name="lbr_1_joint" type="revolute">
    <!--<origin xyz="0 0 0.14" rpy="0 0 -2.8407"/> -->
    <origin rpy="0 0 0" xyz="0 0 0.1105"/>
    <parent link="lbr_0_link"/>
    <child link="lbr_1_link"/>
    <axis xyz="0 0 1"/>
    <dynamics damping="25"/>
    <limit effort="200" lower="-2.9670" upper="2.9670" velocity="1.9634"/>
  </joint>
  <link name="lbr_1_link">
    <inertial>
      <origin rpy="0 0 0" xyz="0 0 0"/>
      <mass value="5.9907"/>
      <inertia ixx="0.01" ixy="0" ixz="0" iyy="0.01" iyz="0" izz="0.01"/>
    </inertial>
    <visual>
      <origin rpy="0 0 0" xyz="0 0 0"/>
      <geometry>
        <mesh filename="package://omnirob_description/meshes/lbr1.stl"/>
      </geometry>
      <material name="Blue"/>
    </visual>
    <collision>
      <origin rpy="0 0 0" xyz="0 0 0"/>
      <geometry>
        <mesh filename="package://omnirob_description/meshes/lbr1_low_res.stl"/>
      </geometry>
    </collision>
  </link>
  <joint name="lbr_2_joint" type="revolute">
    <origin rpy="1.5708 0 0" xyz="0 0 0.1915"/>
    <parent link="lbr_1_link"/>
    <child link="lbr_2_link"/>
    <axis xyz="0 0 1"/>
    <dynamics damping="25"/>
    <limit effort="200" lower="-2.0943" upper="2.0943" velocity="1.9634"/>
  </joint>
  <link name="lbr_2_link">
    <inertial>
      <origin rpy="0 0 0" xyz="0 0 0.002"/>
      <mass value="5.734939"/>
      <inertia ixx="0.03" ixy="0" ixz="0" iyy="0.03" iyz="0" izz="0.03"/>
    </inertial>
    <visual>
      <origin rpy="0 0 0" xyz="0 0 0.002"/>
      <geometry>
        <mesh filename="package://omnirob_description/meshes/lbr2.stl"/>
      </geometry>
      <material name="Red"/>
    </visual>
    <collision>
      <origin rpy="0 0 0" xyz="0 0 0.002"/>
      <geometry>
        <mesh filename="package://omnirob_description/meshes/lbr2_low_res.stl"/>
      </geometry>
    </collision>
  </link>
  <joint name="lbr_3_joint" type="revolute">
    <origin rpy="-1.5708 0 0" xyz="0 0.2085 0"/>
    <parent link="lbr_2_link"/>
    <child link="lbr_3_link"/>
    <axis xyz="0 0 1"/>
    <dynamics damping="25"/>
    <limit effort="100" lower="-2.9670" upper="2.9670" velocity="1.9634"/>
  </joint>
  <link name="lbr_3_link">
    <inertial>
      <origin rpy="0 0 0" xyz="0 -0.002 0"/>
      <mass value="4.214668"/>
      <inertia ixx="0.03" ixy="0" ixz="0" iyy="0.03" iyz="0" izz="0.03"/>
    </inertial>
    <visual>
      <origin rpy="0 0 0" xyz="0 -0.002 0"/>
      <geometry>
        <mesh filename="package://omnirob_description/meshes/lbr3.stl"/>
      </geometry>
      <material name="Blue"/>
    </visual>
    <collision>
      <origin rpy="0 0 0" xyz="0 -0.002 0"/>
      <geometry>
        <mesh filename="package://omnirob_description/meshes/lbr3_low_res.stl"/>
      </geometry>
    </collision>
  </link>
  <joint name="lbr_4_joint" type="revolute">
    <origin rpy="-1.5708 0 0" xyz="0 0 0.1915"/>
    <parent link="lbr_3_link"/>
    <child link="lbr_4_link"/>
    <axis xyz="0 0 1"/>
    <dynamics damping="25"/>
    <limit effort="100" lower="-2.0943" upper="2.0943" velocity="1.9634"/>
  </joint>
  <link name="lbr_4_link">
    <inertial>
      <origin rpy="0 0 0" xyz="0 0 0"/>
      <mass value="3.669819"/>
      <inertia ixx="0.03" ixy="0" ixz="0" iyy="0.03" iyz="0" izz="0.03"/>
    </inertial>
    <visual>
      <origin rpy="0 0 0" xyz="0 0 0"/>
      <geometry>
        <mesh filename="package://omnirob_description/meshes/lbr4.stl"/>
      </geometry>
      <material name="Red"/>
    </visual>
    <collision>
      <origin rpy="0 0 0" xyz="0 0 0"/>
      <geometry>
        <mesh filename="package://omnirob_description/meshes/lbr4_low_res.stl"/>
      </geometry>
    </collision>
  </link>
  <joint name="lbr_5_joint" type="revolute">
    <origin rpy="1.5708 0 0" xyz="0 -0.2085 0"/>
    <parent link="lbr_4_link"/>
    <child link="lbr_5_link"/>
    <axis xyz="0 0 1"/>
    <dynamics damping="25"/>
    <limit effort="100" lower="-2.9670" upper="2.9670" velocity="3.1415926"/>
  </joint>
  <link name="lbr_5_link">
    <inertial>
      <origin rpy="0 0 0" xyz="0 0 0"/>
      <mass value="2.313272"/>
      <inertia ixx="0.03" ixy="0" ixz="0" iyy="0.03" iyz="0" izz="0.03"/>
    </inertial>
    <visual>
      <origin rpy="0 0 0" xyz="0 0 0"/>
      <geometry>
        <mesh filename="package://omnirob_description/meshes/lbr5.stl"/>
      </geometry>
      <material name="Blue"/>
    </visual>
    <collision>
      <origin rpy="0 0 0" xyz="0 0 0"/>
      <geometry>
        <mesh filename="package://omnirob_description/meshes/lbr5_low_res.stl"/>
      </geometry>
    </collision>
  </link>
  <joint name="lbr_6_joint" type="revolute">
    <origin rpy="1.5708 0 0" xyz="0 0 0.1815"/>
    <parent link="lbr_5_link"/>
    <child link="lbr_6_link"/>
    <axis xyz="0 0 1"/>
    <dynamics damping="25"/>
    <limit effort="30" lower="-2.0943951" upper="2.0943951" velocity="1.9634"/>
  </joint>
  <link name="lbr_6_link">
    <inertial>
      <origin rpy="0 0 0" xyz="0 0 0"/>
      <mass value="2.057856"/>
      <inertia ixx="0.01" ixy="0" ixz="0" iyy="0.01" iyz="0" izz="0.01"/>
    </inertial>
    <visual>
      <origin rpy="0 0 0" xyz="0 0 -0.046"/>
      <geometry>
        <mesh filename="package://omnirob_description/meshes/lbr6.stl"/>
      </geometry>
      <material name="Red"/>
    </visual>
    <collision>
      <origin rpy="0 0 0" xyz="0 0 -0.046"/>
      <geometry>
        <mesh filename="package://omnirob_description/meshes/lbr6_low_res.stl"/>
      </geometry>
    </collision>
  </link>
  <joint name="lbr_7_joint" type="revolute">
    <origin rpy="-1.5708 0 0" xyz="0 0.057 0"/>
    <parent link="lbr_6_link"/>
    <child link="lbr_7_link"/>
    <axis xyz="0 0 1"/>
    <dynamics damping="25"/>
    <limit effort="30" lower="-2.9670" upper="2.9670" velocity="1.9634"/>
  </joint>
  <link name="lbr_7_link">
    <inertial>
      <origin rpy="0 0 0" xyz="0 0 0"/>
      <mass value="1.120198"/>
      <inertia ixx="0.01" ixy="0" ixz="0" iyy="0.01" iyz="0" izz="0.01"/>
    </inertial>
    <visual>
      <origin rpy="0 0 0" xyz="0 0 0"/>
      <geometry>
        <mesh filename="package://omnirob_description/meshes/lbr7.stl"/>
      </geometry>
      <material name="Blue"/>
    </visual>
    <collision>
      <origin rpy="0 0 0" xyz="0 0 0"/>
      <geometry>
        <mesh filename="package://omnirob_description/meshes/lbr7_low_res.stl"/>
      </geometry>
    </collision>
  </link>
  <joint name="flange" type="fixed">
    <parent link="lbr_7_link"/>
    <child link="lbr_flange_link"/>
    <origin rpy="0 0 0" xyz="0 0 0.0195"/>
  </joint>
  <link name="lbr_flange_link">
		</link>
  <link name="sdh2_palm_link">
    <inertial>
      <origin rpy="0 0 0" xyz="0 0 0"/>
      <mass value="1"/>
      <inertia ixx="0.01" ixy="0" ixz="0" iyy="0.01" iyz="0" izz="0.01"/>
    </inertial>
    <visual>
      <origin rpy="0 0 0" xyz="0 0 0"/>
      <geometry>
        <mesh filename="package://sdh2_description/meshes/palm.stl"/>
      </geometry>
      <material name="Schunk/LightGrey"/>
    </visual>
    <collision>
      <origin rpy="0 0 0" xyz="0 0 0"/>
      <geometry>
        <mesh filename="package://sdh2_description/meshes/palm_low_res.stl"/>
      </geometry>
    </collision>
  </link>
  <joint name="sdh2_grasp_joint" type="fixed">
    <origin rpy="0 0 0" xyz="0 0 0.15"/>
    <parent link="sdh2_palm_link"/>
    <child link="sdh2_grasp_link"/>
  </joint>
  <link name="sdh2_grasp_link"/>
  <joint name="sdh2_tip_joint" type="fixed">
    <origin rpy="0 0 0" xyz="0 0 0.22"/>
    <parent link="sdh2_palm_link"/>
    <child link="sdh2_tip_link"/>
  </joint>
  <link name="sdh2_tip_link"/>
  <joint name="sdh2_knuckle_joint" type="revolute">
    <origin rpy="0 0 3.14159265" xyz="0.01905 0.033 0.0745"/>
    <parent link="sdh2_palm_link"/>
    <child link="sdh2_finger_11_link"/>
    <axis xyz="0 0 1"/>
    <dynamics damping="1"/>
    <limit effort="100" lower="0" upper="1.570796327" velocity="5"/>
  </joint>
  <link name="sdh2_finger_11_link">
    <inertial>
      <origin rpy="0 0 0" xyz="0 0 0"/>
      <mass value="0.1"/>
      <inertia ixx="0.01" ixy="0" ixz="0" iyy="0.01" iyz="0" izz="0.01"/>
    </inertial>
    <visual>
      <origin rpy="0 0 0" xyz="0 0 0"/>
      <geometry>
        <mesh filename="package://sdh2_description/meshes/knuckle.stl"/>
      </geometry>
      <material name="Schunk/LightGrey"/>
    </visual>
    <collision>
      <origin rpy="0 0 0" xyz="0 0 0"/>
      <geometry>
        <mesh filename="package://sdh2_description/meshes/knuckle_low_res.stl"/>
      </geometry>
    </collision>
  </link>
  <joint name="sdh2_finger_12_joint" type="revolute">
    <origin rpy="0 0 0" xyz="0 0 0.0165"/>
    <parent link="sdh2_finger_11_link"/>
    <child link="sdh2_finger_12_link"/>
    <axis xyz="0 1 0"/>
    <dynamics damping="1"/>
    <limit effort="100" lower="-1.570796327" upper="1.570796327" velocity="5"/>
  </joint>
  <link name="sdh2_finger_12_link">
    <inertial>
      <origin rpy="0 0 0" xyz="0 0 0"/>
      <mass value="0.1"/>
      <inertia ixx="0.01" ixy="0" ixz="0" iyy="0.01" iyz="0" izz="0.01"/>
    </inertial>
    <visual>
      <origin rpy="0 0 0" xyz="0 0 0"/>
      <geometry>
        <mesh filename="package://sdh2_description/meshes/finger.stl"/>
      </geometry>
      <material name="Schunk/LightGrey"/>
    </visual>
    <collision>
      <origin rpy="0 0 0" xyz="0 0 0"/>
      <geometry>
        <mesh filename="package://sdh2_description/meshes/finger_low_res.stl"/>
      </geometry>
    </collision>
  </link>
  <joint name="sdh2_finger_13_joint" type="revolute">
    <origin rpy="0 0 0" xyz="0 0 0.0865"/>
    <parent link="sdh2_finger_12_link"/>
    <child link="sdh2_finger_13_link"/>
    <axis xyz="0 1 0"/>
    <dynamics damping="1"/>
    <limit effort="100" lower="-1.570796327" upper="1.570796327" velocity="5"/>
  </joint>
  <link name="sdh2_finger_13_link">
    <inertial>
      <origin rpy="0 0 0" xyz="0 0 0"/>
      <mass value="0.1"/>
      <inertia ixx="0.01" ixy="0" ixz="0" iyy="0.01" iyz="0" izz="0.01"/>
    </inertial>
    <visual>
      <origin rpy="0 0 0" xyz="0 0 0"/>
      <geometry>
        <mesh filename="package://sdh2_description/meshes/finger_tip.stl"/>
      </geometry>
      <material name="Schunk/LightGrey"/>
    </visual>
    <collision>
      <origin rpy="0 0 0" xyz="0 0 0"/>
      <geometry>
        <mesh filename="package://sdh2_description/meshes/finger_tip_low_res.stl"/>
      </geometry>
    </collision>
  </link>
  <joint name="sdh2_finger_21_joint" type="revolute">
    <mimic joint="sdh2_knuckle_joint" multiplier="1" offset="0"/>
    <origin rpy="0 0 3.14159265" xyz="0.01905 -0.033 0.0745"/>
    <parent link="sdh2_palm_link"/>
    <child link="sdh2_finger_21_link"/>
    <axis xyz="0 0 -1"/>
    <dynamics damping="1"/>
    <limit effort="100" lower="0" upper="1.570796327" velocity="5"/>
  </joint>
  <link name="sdh2_finger_21_link">
    <inertial>
      <origin rpy="0 0 0" xyz="0 0 0"/>
      <mass value="0.1"/>
      <inertia ixx="0.01" ixy="0" ixz="0" iyy="0.01" iyz="0" izz="0.01"/>
    </inertial>
    <visual>
      <origin rpy="0 0 0" xyz="0 0 0"/>
      <geometry>
        <mesh filename="package://sdh2_description/meshes/knuckle.stl"/>
      </geometry>
      <material name="Schunk/LightGrey"/>
    </visual>
    <collision>
      <origin rpy="0 0 0" xyz="0 0 0"/>
      <geometry>
        <mesh filename="package://sdh2_description/meshes/knuckle_low_res.stl"/>
      </geometry>
    </collision>
  </link>
  <joint name="sdh2_finger_22_joint" type="revolute">
    <origin rpy="0 0 0" xyz="0 0 0.0165"/>
    <parent link="sdh2_finger_21_link"/>
    <child link="sdh2_finger_22_link"/>
    <axis xyz="0 1 0"/>
    <dynamics damping="1"/>
    <limit effort="100" lower="-1.570796327" upper="1.570796327" velocity="5"/>
  </joint>
  <link name="sdh2_finger_22_link">
    <inertial>
      <origin rpy="0 0 0" xyz="0 0 0"/>
      <mass value="0.1"/>
      <inertia ixx="0.01" ixy="0" ixz="0" iyy="0.01" iyz="0" izz="0.01"/>
    </inertial>
    <visual>
      <origin rpy="0 0 0" xyz="0 0 0"/>
      <geometry>
        <mesh filename="package://sdh2_description/meshes/finger.stl"/>
      </geometry>
      <material name="Schunk/LightGrey"/>
    </visual>
    <collision>
      <origin rpy="0 0 0" xyz="0 0 0"/>
      <geometry>
        <mesh filename="package://sdh2_description/meshes/finger_low_res.stl"/>
      </geometry>
    </collision>
  </link>
  <joint name="sdh2_finger_23_joint" type="revolute">
    <origin rpy="0 0 0" xyz="0 0 0.0865"/>
    <parent link="sdh2_finger_22_link"/>
    <child link="sdh2_finger_23_link"/>
    <axis xyz="0 1 0"/>
    <dynamics damping="1"/>
    <limit effort="100" lower="-1.570796327" upper="1.570796327" velocity="5"/>
  </joint>
  <link name="sdh2_finger_23_link">
    <inertial>
      <origin rpy="0 0 0" xyz="0 0 0"/>
      <mass value="0.1"/>
      <inertia ixx="0.01" ixy="0" ixz="0" iyy="0.01" iyz="0" izz="0.01"/>
    </inertial>
    <visual>
      <origin rpy="0 0 0" xyz="0 0 0"/>
      <geometry>
        <mesh filename="package://sdh2_description/meshes/finger_tip.stl"/>
      </geometry>
      <material name="Schunk/LightGrey"/>
    </visual>
    <collision>
      <origin rpy="0 0 0" xyz="0 0 0"/>
      <geometry>
        <mesh filename="package://sdh2_description/meshes/finger_tip_low_res.stl"/>
      </geometry>
    </collision>
  </link>
  <joint name="sdh2_thumb_1_joint" type="fixed">
    <origin rpy="0 0 0" xyz="-0.03811 0 0.0745 "/>
    <parent link="sdh2_palm_link"/>
    <child link="sdh2_thumb_1_link"/>
  </joint>
  <link name="sdh2_thumb_1_link">
    <inertial>
      <origin rpy="0 0 0" xyz="0 0 0"/>
      <mass value="0.1"/>
      <inertia ixx="0.01" ixy="0" ixz="0" iyy="0.01" iyz="0" izz="0.01"/>
    </inertial>
    <visual>
      <origin rpy="0 0 0" xyz="0 0 0"/>
      <geometry>
        <mesh filename="package://sdh2_description/meshes/knuckle.stl"/>
      </geometry>
      <material name="Schunk/LightGrey"/>
    </visual>
    <collision>
      <origin rpy="0 0 0" xyz="0 0 0"/>
      <geometry>
        <mesh filename="package://sdh2_description/meshes/knuckle_low_res.stl"/>
      </geometry>
    </collision>
  </link>
  <joint name="sdh2_thumb_2_joint" type="revolute">
    <origin rpy="0 0 0" xyz="0 0 0.0165"/>
    <parent link="sdh2_thumb_1_link"/>
    <child link="sdh2_thumb_2_link"/>
    <axis xyz="0 1 0"/>
    <dynamics damping="1"/>
    <limit effort="100" lower="-1.570796327" upper="1.570796327" velocity="5"/>
  </joint>
  <link name="sdh2_thumb_2_link">
    <inertial>
      <origin rpy="0 0 0" xyz="0 0 0"/>
      <mass value="0.1"/>
      <inertia ixx="0.01" ixy="0" ixz="0" iyy="0.01" iyz="0" izz="0.01"/>
    </inertial>
    <visual>
      <origin rpy="0 0 0" xyz="0 0 0"/>
      <geometry>
        <mesh filename="package://sdh2_description/meshes/finger.stl"/>
      </geometry>
      <material name="Schunk/LightGrey"/>
    </visual>
    <collision>
      <origin rpy="0 0 0" xyz="0 0 0"/>
      <geometry>
        <mesh filename="package://sdh2_description/meshes/finger_low_res.stl"/>
      </geometry>
    </collision>
  </link>
  <joint name="sdh2_thumb_3_joint" type="revolute">
    <origin rpy="0 0 0" xyz="0 0 0.0865"/>
    <parent link="sdh2_thumb_2_link"/>
    <child link="sdh2_thumb_3_link"/>
    <axis xyz="0 1 0"/>
    <dynamics damping="1"/>
    <limit effort="100" lower="-1.570796327" upper="1.570796327" velocity="5"/>
  </joint>
  <link name="sdh2_thumb_3_link">
    <inertial>
      <origin rpy="0 0 0" xyz="0 0 0"/>
      <mass value="0.1"/>
      <inertia ixx="0.01" ixy="0" ixz="0" iyy="0.01" iyz="0" izz="0.01"/>
    </inertial>
    <visual>
      <origin rpy="0 0 0" xyz="0 0 0"/>
      <geometry>
        <mesh filename="package://sdh2_description/meshes/finger_tip.stl"/>
      </geometry>
      <material name="Schunk/LightGrey"/>
    </visual>
    <collision>
      <origin rpy="0 0 0" xyz="0 0 0"/>
      <geometry>
        <mesh filename="package://sdh2_description/meshes/finger_tip_low_res.stl"/>
      </geometry>
    </collision>
  </link>
  <gazebo reference="sdh2_palm_link">
    <material>Schunk/LightGrey</material>
    <turnGravityOff>false</turnGravityOff>
  </gazebo>
  <gazebo reference="sdh2_finger_11_link">
    <material>Schunk/LightGrey</material>
    <turnGravityOff>false</turnGravityOff>
  </gazebo>
  <gazebo reference="sdh2_finger_12_link">
    <selfCollide>true</selfCollide>
    <material>Schunk/LightGrey</material>
    <turnGravityOff>false</turnGravityOff>
  </gazebo>
  <gazebo reference="sdh2_finger_13_link">
    <selfCollide>true</selfCollide>
    <material>Schunk/LightGrey</material>
  </gazebo>
  <gazebo reference="sdh2_finger_21_link">
    <material>Schunk/LightGrey</material>
    <turnGravityOff>false</turnGravityOff>
  </gazebo>
  <gazebo reference="sdh2_finger_22_link">
    <selfCollide>true</selfCollide>
    <material>Schunk/LightGrey</material>
    <turnGravityOff>false</turnGravityOff>
  </gazebo>
  <gazebo reference="sdh2_finger_23_link">
    <selfCollide>true</selfCollide>
    <material>Schunk/LightGrey</material>
  </gazebo>
  <gazebo reference="sdh2_thumb_1_link">
    <material>Schunk/LightGrey</material>
    <turnGravityOff>false</turnGravityOff>
  </gazebo>
  <gazebo reference="sdh2_thumb_2_link">
    <selfCollide>true</selfCollide>
    <material>Schunk/LightGrey</material>
    <turnGravityOff>false</turnGravityOff>
  </gazebo>
  <gazebo reference="sdh2_thumb_3_link">
    <selfCollide>true</selfCollide>
    <material>Schunk/LightGrey</material>
  </gazebo>
  <transmission name="sdh2_knuckle_trans" type="pr2_mechanism_model/SimpleTransmission">
    <actuator name="sdh2_knuckle_motor"/>
    <joint name="sdh2_finger_21_joint"/>
    <mechanicalReduction>1</mechanicalReduction>
  </transmission>
  <transmission name="sdh2_knuckle_trans" type="pr2_mechanism_model/SimpleTransmission">
    <actuator name="sdh2_knuckle_motor"/>
    <joint name="sdh2_knuckle_joint"/>
    <mechanicalReduction>1</mechanicalReduction>
  </transmission>
  <transmission name="sdh2_finger_12_trans" type="pr2_mechanism_model/SimpleTransmission">
    <actuator name="sdh2_finger_12_motor"/>
    <joint name="sdh2_finger_12_joint"/>
    <mechanicalReduction>1</mechanicalReduction>
  </transmission>
  <transmission name="sdh2_finger_13_trans" type="pr2_mechanism_model/SimpleTransmission">
    <actuator name="sdh2_finger_13_motor"/>
    <joint name="sdh2_finger_13_joint"/>
    <mechanicalReduction>1</mechanicalReduction>
  </transmission>
  <transmission name="sdh2_finger_22_trans" type="pr2_mechanism_model/SimpleTransmission">
    <actuator name="sdh2_finger_22_motor"/>
    <joint name="sdh2_finger_22_joint"/>
    <mechanicalReduction>1</mechanicalReduction>
  </transmission>
  <transmission name="sdh2_finger_23_trans" type="pr2_mechanism_model/SimpleTransmission">
    <actuator name="sdh2_finger_23_motor"/>
    <joint name="sdh2_finger_23_joint"/>
    <mechanicalReduction>1</mechanicalReduction>
  </transmission>
  <transmission name="sdh2_thumb_2_trans" type="pr2_mechanism_model/SimpleTransmission">
    <actuator name="sdh2_thumb_2_motor"/>
    <joint name="sdh2_thumb_2_joint"/>
    <mechanicalReduction>1</mechanicalReduction>
  </transmission>
  <transmission name="sdh2_thumb_3_trans" type="pr2_mechanism_model/SimpleTransmission">
    <actuator name="sdh2_thumb_3_motor"/>
    <joint name="sdh2_thumb_3_joint"/>
    <mechanicalReduction>1</mechanicalReduction>
  </transmission>
  <joint name="sdh2_palm_joint" type="fixed">
    <origin rpy="0 0 0" xyz="0 0 0"/>
    <parent link="lbr_flange_link"/>
    <child link="sdh2_palm_link"/>
  </joint>
</robot>
