<?xml version="1.0" ?>
<!-- =================================================================================== -->
<!-- | This document was autogenerated by xacro from omnirob_lbr_wsg.xacro | -->
<!-- | EDITING THIS FILE BY HAND IS NOT RECOMMENDED | -->
<!-- =================================================================================== -->
<robot name="omnirob" xmlns:controller="http://playerstage.sourceforge.net/gazebo/xmlschema/#controller" xmlns:interface="http://playerstage.sourceforge.net/gazebo/xmlschema/#interface" xmlns:sensor="http://playerstage.sourceforge.net/gazebo/xmlschema/#sensor" xmlns:xacro="http://ros.org/wiki/xacro">
	<!-- ros_control plugin -->
	<gazebo>
		<plugin filename="libgazebo_ros_control.so" name="gazebo_ros_control">
			<robotNamespace>/lbr</robotNamespace>
			<robotSimType>gazebo_ros_control/DefaultRobotHWSim</robotSimType>
		</plugin>
	</gazebo>
	<!-- Link0 -->
	<gazebo reference="lbr_0_link">
		<material>Gazebo/Blue</material>
	</gazebo>
	<!-- Link1 -->
	<gazebo reference="lbr_1_link">
		<material>Gazebo/Red</material>
	</gazebo>
	<!-- Link2 -->
	<gazebo reference="lbr_2_link">
		<material>Gazebo/Blue</material>
	</gazebo>
	<!-- Link3 -->
	<gazebo reference="lbr_3_link">
		<material>Gazebo/Red</material>
	</gazebo>
	<!-- Link4 -->
	<gazebo reference="lbr_4_link">
		<material>Gazebo/Blue</material>
	</gazebo>
	<!-- Link5 -->
	<gazebo reference="lbr_5_link">
		<material>Gazebo/Red</material>
	</gazebo>
	<!-- Link6 -->
	<gazebo reference="lbr_6_link">
		<material>Gazebo/Blue</material>
	</gazebo>
	<!-- Link7 -->
	<gazebo reference="lbr_7_link">
		<material>Gazebo/Red</material>
	</gazebo>
	<material name="Blue">
		<color rgba="0.0 0.0 0.8 1.0" />
	</material>
	<material name="Green">
		<color rgba="0.0 0.8 0.0 1.0" />
	</material>
	<material name="Grey">
		<color rgba="0.7 0.7 0.7 1.0" />
	</material>
	<material name="Grey2">
		<color rgba="0.9 0.9 0.9 1.0" />
	</material>
	<material name="Red">
		<color rgba="0.8 0.0 0.0 1.0" />
	</material>
	<material name="orange">
		<color rgba="1.0 0.423529411765 0.0392156862745 1.0" />
	</material>
	<material name="brown">
		<color rgba="0.870588235294 0.811764705882 0.764705882353 1.0" />
	</material>
	<material name="White">
		<color rgba="1.0 1.0 1.0 1.0" />
	</material>
	<material name="Black">
		<color rgba="0.0 0.0 0.0 1.0" />
	</material>
	<material name="pole_gray">
		<color rgba="0.9 0.9 0.9 1.0" />
	</material>
	<material name="asus_xtion_gray">
		<color rgba="0.6 0.6 0.6 1.0" />
	</material>
	<material name="Gray">
		<color rgba="0.25 0.25 0.25 1.0" />
	</material>

	<link name="base_link">
		<visual>
			<geometry>
				<sphere radius="0.0" />
			</geometry>
			<material name="blue">
				<color rgba="0.0 0.0 0.8 1.0" />
			</material>
		</visual>
	</link>


	<link name="base_x_link">
		<visual>
			<geometry>
				<sphere radius="0.0" />
			</geometry>
			<material name="blue">
				<color rgba="0.0 0.0 0.8 1.0" />
			</material>
		</visual>
	</link>


	<joint name="base_x_joint" type="prismatic">
		<parent link="base_link" />
		<child link="base_x_link" />
		<limit effort="1000.0" lower="-100.0" upper="100.0" velocity="0.5" />
		<axis xyz="1 0 0" />
		<!-- <origin rpy="0 1.57075 0" xyz="0 0 0"/> -->
	</joint>


	<link name="base_y_link">
		<visual>
			<geometry>
				<sphere radius="0.0" />
			</geometry>
			<material name="blue">
				<color rgba="0.0 0.0 0.8 1.0" />
			</material>
		</visual>
	</link>


	<joint name="base_y_joint" type="prismatic">
		<parent link="base_x_link" />
		<child link="base_y_link" />
		<axis xyz="0 1 0" />
		<limit effort="1000.0" lower="-100.0" upper="100.0" velocity="0.5" />
		<!-- <origin rpy="-1.57075 0 0" xyz="0 0 0"/> -->
	</joint>


	<link name="platform_link">
		<visual>
			<geometry>
				<sphere radius="0.0" />
			</geometry>
			<material name="blue">
				<color rgba="0.0 0.0 0.8 1.0" />
			</material>
		</visual>
	</link>


	<joint name="platform_joint" type="fixed">
		<parent link="base_y_link" />
		<child link="platform_link" />
		<limit effort="1000.0" lower="-10.0" upper="10.0" velocity="0.5" />
		<origin rpy="0 0 0" xyz="0 0 0" />
	</joint>


	<link name="base_theta_link">
		<visual>
			<geometry>
				<sphere radius="0.0" />
			</geometry>
			<material name="blue">
				<color rgba="0.0 0.0 0.8 1.0" />
			</material>
		</visual>
	</link>


	<joint name="base_theta_joint" type="continuous">
		<origin rpy="0 0 0" xyz="0 0 0" />
		<parent link="platform_link" />
		<child link="base_theta_link" />
		<axis xyz="0 0 1" />
		<!-- <limit effort="1000.0" lower="-3.1415" upper="3.1415" velocity="1.9634"/> -->
	</joint>



	<link name="base_box_link">
		<visual>
			<origin rpy="0 0 0" xyz="0 0 0" />
			<geometry>
				<mesh filename="package://omnirob_description/meshes/omnirob_hull.stl" scale="0.001 0.001 0.001" />
			</geometry>
			<material name="Gray" />
		</visual>
		<collision>
			<origin rpy="0 0 0" xyz="0 0 0" />
			<geometry>
				<mesh filename="package://omnirob_description/meshes/omnirob_hull_low_res.stl" scale="0.001 0.001 0.001" />
			</geometry>
		</collision>
	</link>


	<joint name="base_box_joint" type="fixed">
		<parent link="base_theta_link" />
		<child link="base_box_link" />
		<limit effort="1000.0" lower="-10.0" upper="10.0" velocity="0.5" />
		<origin rpy="0 0 0" xyz="0 0 0" />
	</joint>

	<link name="laser_front_link">
	</link>
	<link name="laser_rear_link">
	</link>
	<joint name="laser_front_joint" type="fixed">
		<parent link="base_box_link" />
		<child link="laser_front_link" />
		<origin rpy="0 0 -0.78893" xyz="0.542477 -0.317722 0.13664" />
	</joint>
	<joint name="laser_rear_joint" type="fixed">
		<parent link="base_link" />
		<child link="laser_rear_link" />
		<origin rpy="0 0 2.31624" xyz="-0.534443 0.32895 0.13664" />
	</joint>
	<!-- Used for fixing robot to Gazebo 'base_link' -->
	<!--<link name="world"/> <joint name="fixed" type="fixed"> <parent link="world"/> <child link="${name}_0_link"/> </joint> -->
	<link name="lbr_0_link">
		<inertial>
			<origin rpy="0 0 0" xyz="0 0 0" />
			<mass value="1.0" />
			<inertia ixx="0.01" ixy="0" ixz="0" iyy="0.01" iyz="0" izz="0.01" />
		</inertial>
		<visual>
			<origin rpy="0 0 0" xyz="0 0 0" />
			<geometry>
				<mesh filename="package://omnirob_description/meshes/lbr0.stl" />
			</geometry>
			<material name="Blue" />
		</visual>
		<collision>
			<origin rpy="0 0 0" xyz="0 0 0" />
			<geometry>
				<mesh filename="package://omnirob_description/meshes/lbr0_low_res.stl" />
			</geometry>
		</collision>
	</link>
	<!-- joint between arm_0_link and arm_1_link -->
	<joint name="lbr_1_joint" type="revolute">
		<!--<origin xyz="0 0 0.14" rpy="0 0 -2.8407"/> -->
		<origin rpy="0 0 0" xyz="0 0 0.1105" />
		<parent link="lbr_0_link" />
		<child link="lbr_1_link" />
		<axis xyz="0 0 1" />
		<dynamics damping="25" />
		<limit effort="200" lower="-2.9670" upper="2.9670" velocity="1.9634" />
	</joint>
	<link name="lbr_1_link">
		<inertial>
			<origin rpy="0 0 0" xyz="0 0 0" />
			<mass value="5.9907" />
			<inertia ixx="0.01" ixy="0" ixz="0" iyy="0.01" iyz="0" izz="0.01" />
		</inertial>
		<visual>
			<origin rpy="0 0 0" xyz="0 0 0" />
			<geometry>
				<mesh filename="package://omnirob_description/meshes/lbr1.stl" />
			</geometry>
			<material name="Blue" />
		</visual>
		<collision>
			<origin rpy="0 0 0" xyz="0 0 0" />
			<geometry>
				<mesh filename="package://omnirob_description/meshes/lbr1_low_res.stl" />
			</geometry>
		</collision>
	</link>
	<!-- joint between arm_1_link and arm_2_link -->
	<joint name="lbr_2_joint" type="revolute">
		<origin rpy="1.5708 0 0" xyz="0 0 0.1915" />
		<parent link="lbr_1_link" />
		<child link="lbr_2_link" />
		<axis xyz="0 0 1" />
		<dynamics damping="25" />
		<limit effort="200" lower="-2.0943" upper="2.0943" velocity="1.9634" />
	</joint>
	<link name="lbr_2_link">
		<inertial>
			<origin rpy="0 0 0" xyz="0 0 0.002" />
			<mass value="5.734939" />
			<inertia ixx="0.03" ixy="0" ixz="0" iyy="0.03" iyz="0" izz="0.03" />
		</inertial>
		<visual>
			<origin rpy="0 0 0" xyz="0 0 0.002" />
			<geometry>
				<mesh filename="package://omnirob_description/meshes/lbr2.stl" />
			</geometry>
			<material name="Red" />
		</visual>
		<collision>
			<origin rpy="0 0 0" xyz="0 0 0.002" />
			<geometry>
				<mesh filename="package://omnirob_description/meshes/lbr2_low_res.stl" />
			</geometry>
		</collision>
	</link>
	<!-- joint between arm_2_link and arm_3_link -->
	<joint name="lbr_3_joint" type="revolute">
		<origin rpy="-1.5708 0 0" xyz="0 0.2085 0" />
		<parent link="lbr_2_link" />
		<child link="lbr_3_link" />
		<axis xyz="0 0 1" />
		<dynamics damping="25" />
		<limit effort="100" lower="-2.9670" upper="2.9670" velocity="1.9634" />
	</joint>
	<link name="lbr_3_link">
		<inertial>
			<origin rpy="0 0 0" xyz="0 -0.002 0" />
			<mass value="4.214668" />
			<inertia ixx="0.03" ixy="0" ixz="0" iyy="0.03" iyz="0" izz="0.03" />
		</inertial>
		<visual>
			<origin rpy="0 0 0" xyz="0 -0.002 0" />
			<geometry>
				<mesh filename="package://omnirob_description/meshes/lbr3.stl" />
			</geometry>
			<material name="Blue" />
		</visual>
		<collision>
			<origin rpy="0 0 0" xyz="0 -0.002 0" />
			<geometry>
				<mesh filename="package://omnirob_description/meshes/lbr3_low_res.stl" />
			</geometry>
		</collision>
	</link>
	<!-- joint between arm_3_link and arm_4_link -->
	<joint name="lbr_4_joint" type="revolute">
		<origin rpy="-1.5708 0 0" xyz="0 0 0.1915" />
		<parent link="lbr_3_link" />
		<child link="lbr_4_link" />
		<axis xyz="0 0 1" />
		<dynamics damping="25" />
		<limit effort="100" lower="-2.0943" upper="2.0943" velocity="1.9634" />
	</joint>
	<link name="lbr_4_link">
		<inertial>
			<origin rpy="0 0 0" xyz="0 0 0" />
			<mass value="3.669819" />
			<inertia ixx="0.03" ixy="0" ixz="0" iyy="0.03" iyz="0" izz="0.03" />
		</inertial>
		<visual>
			<origin rpy="0 0 0" xyz="0 0 0" />
			<geometry>
				<mesh filename="package://omnirob_description/meshes/lbr4.stl" />
			</geometry>
			<material name="Red" />
		</visual>
		<collision>
			<origin rpy="0 0 0" xyz="0 0 0" />
			<geometry>
				<mesh filename="package://omnirob_description/meshes/lbr4_low_res.stl" />
			</geometry>
		</collision>
	</link>
	<!-- joint between arm_4_link and arm_5_link -->
	<joint name="lbr_5_joint" type="revolute">
		<origin rpy="1.5708 0 0" xyz="0 -0.2085 0" />
		<parent link="lbr_4_link" />
		<child link="lbr_5_link" />
		<axis xyz="0 0 1" />
		<dynamics damping="25" />
		<limit effort="100" lower="-2.9670" upper="2.9670" velocity="3.1415926" />
	</joint>
	<link name="lbr_5_link">
		<inertial>
			<origin rpy="0 0 0" xyz="0 0 0" />
			<mass value="2.313272" />
			<inertia ixx="0.03" ixy="0" ixz="0" iyy="0.03" iyz="0" izz="0.03" />
		</inertial>
		<visual>
			<origin rpy="0 0 0" xyz="0 0 0" />
			<geometry>
				<mesh filename="package://omnirob_description/meshes/lbr5.stl" />
			</geometry>
			<material name="Blue" />
		</visual>
		<collision>
			<origin rpy="0 0 0" xyz="0 0 0" />
			<geometry>
				<mesh filename="package://omnirob_description/meshes/lbr5_low_res.stl" />
			</geometry>
		</collision>
	</link>
	<!-- joint between arm_5_link and arm_6_link -->
	<joint name="lbr_6_joint" type="revolute">
		<origin rpy="1.5708 0 0" xyz="0 0 0.1815" />
		<parent link="lbr_5_link" />
		<child link="lbr_6_link" />
		<axis xyz="0 0 1" />
		<dynamics damping="25" />
		<limit effort="30" lower="-2.0943951" upper="2.0943951" velocity="1.9634" />
	</joint>
	<link name="lbr_6_link">
		<inertial>
			<origin rpy="0 0 0" xyz="0 0 0" />
			<mass value="2.057856" />
			<inertia ixx="0.01" ixy="0" ixz="0" iyy="0.01" iyz="0" izz="0.01" />
		</inertial>
		<visual>
			<origin rpy="0 0 0" xyz="0 0 -0.046" />
			<geometry>
				<mesh filename="package://omnirob_description/meshes/lbr6.stl" />
			</geometry>
			<material name="Red" />
		</visual>
		<collision>
			<origin rpy="0 0 0" xyz="0 0 -0.046" />
			<geometry>
				<mesh filename="package://omnirob_description/meshes/lbr6_low_res.stl" />
			</geometry>
		</collision>
	</link>
	<!-- joint between arm_6_link and arm_7_link -->
	<joint name="lbr_7_joint" type="revolute">
		<origin rpy="-1.5708 0 0" xyz="0 0.057 0" />
		<parent link="lbr_6_link" />
		<child link="lbr_7_link" />
		<axis xyz="0 0 1" />
		<dynamics damping="25" />
		<limit effort="30" lower="-2.9670" upper="2.9670" velocity="1.9634" />
	</joint>
	<link name="lbr_7_link">
		<inertial>
			<origin rpy="0 0 0" xyz="0 0 0" />
			<mass value="1.120198" />
			<inertia ixx="0.01" ixy="0" ixz="0" iyy="0.01" iyz="0" izz="0.01" />
		</inertial>
		<visual>
			<origin rpy="0 0 0" xyz="0 0 0" />
			<geometry>
				<mesh filename="package://omnirob_description/meshes/lbr7.stl" />
			</geometry>
			<material name="Blue" />
		</visual>
		<collision>
			<origin rpy="0 0 0" xyz="0 0 0" />
			<geometry>
				<mesh filename="package://omnirob_description/meshes/lbr7_low_res.stl" />
			</geometry>
		</collision>
	</link>
	<joint name="flange" type="fixed">
		<parent link="lbr_7_link" />
		<child link="lbr_flange_link" />
		<origin rpy="0 0 0" xyz="0 0 0.0195" />
	</joint>
	<link name="lbr_flange_link">
	</link>
	<transmission name="lbr_1_joint_trans">
		<type>pr2_mechanism_model/SimpleTransmission</type>
		<joint name="lbr_1_joint">
			<hardwareInterface>EffortJointInterface</hardwareInterface>
		</joint>
		<actuator name="lbr_1_joint_motor">
			<hardwareInterface>EffortJointInterface</hardwareInterface>
			<mechanicalReduction>1</mechanicalReduction>
		</actuator>
	</transmission>
	<transmission name="lbr_2_joint_trans">
		<type>pr2_mechanism_model/SimpleTransmission</type>
		<joint name="lbr_2_joint">
			<hardwareInterface>EffortJointInterface</hardwareInterface>
		</joint>
		<actuator name="lbr_2_joint_motor">
			<hardwareInterface>EffortJointInterface</hardwareInterface>
			<mechanicalReduction>1</mechanicalReduction>
		</actuator>
	</transmission>
	<transmission name="lbr_3_joint_trans">
		<type>pr2_mechanism_model/SimpleTransmission</type>
		<joint name="lbr_3_joint">
			<hardwareInterface>EffortJointInterface</hardwareInterface>
		</joint>
		<actuator name="lbr_3_joint_motor">
			<hardwareInterface>EffortJointInterface</hardwareInterface>
			<mechanicalReduction>1</mechanicalReduction>
		</actuator>
	</transmission>
	<transmission name="lbr_4_joint_trans">
		<type>pr2_mechanism_model/SimpleTransmission</type>
		<joint name="lbr_4_joint">
			<hardwareInterface>EffortJointInterface</hardwareInterface>
		</joint>
		<actuator name="lbr_4_joint_motor">
			<hardwareInterface>EffortJointInterface</hardwareInterface>
			<mechanicalReduction>1</mechanicalReduction>
		</actuator>
	</transmission>
	<transmission name="lbr_5_joint_trans">
		<type>pr2_mechanism_model/SimpleTransmission</type>
		<actuator name="lbr_5_joint_motor">
			<hardwareInterface>EffortJointInterface</hardwareInterface>
			<mechanicalReduction>1</mechanicalReduction>
		</actuator>
		<joint name="lbr_5_joint">
			<hardwareInterface>EffortJointInterface</hardwareInterface>
		</joint>
	</transmission>
	<transmission name="lbr_6_joint_trans">
		<type>pr2_mechanism_model/SimpleTransmission</type>
		<actuator name="lbr_6_joint_motor">
			<hardwareInterface>EffortJointInterface</hardwareInterface>
			<mechanicalReduction>1</mechanicalReduction>
		</actuator>
		<joint name="lbr_6_joint">
			<hardwareInterface>EffortJointInterface</hardwareInterface>
		</joint>
	</transmission>
	<transmission name="lbr_7_joint_trans">
		<type>pr2_mechanism_model/SimpleTransmission</type>
		<actuator name="lbr_7_joint_motor">
			<hardwareInterface>EffortJointInterface</hardwareInterface>
			<mechanicalReduction>1</mechanicalReduction>
		</actuator>
		<joint name="lbr_7_joint">
			<hardwareInterface>EffortJointInterface</hardwareInterface>
		</joint>
	</transmission>
	<joint name="omnirob_base_joint" type="fixed">
		<origin rpy="0 0 -1.5708" xyz="0.42 0.18 0.65" />
		<parent link="base_link" />
		<child link="lbr_0_link" />
	</joint>
	<joint name="pole_base_joint" type="fixed">
		<origin rpy="0 0 0" xyz="-0.35 -0.25 0.64" />
		<parent link="base_link" />
		<child link="pole_base_link" />
	</joint>
	<link name="pole_base_link">
		<visual>
			<geometry>
				<box size="0.08 0.08 1.01" />
			</geometry>
			<origin xyz="0.04 0.04 0.505" />
			<material name="pole_gray" />
		</visual>
		<collision>
			<geometry>
				<box size="0.08 0.08 1.01" />
			</geometry>
			<origin xyz="0.04 0.04 0.505" />
		</collision>
	</link>
	<joint name="pole_top_joint" type="fixed">
		<parent link="pole_base_link" />
		<child link="pole_top_link" />
		<origin rpy="0 0 0" xyz="0 0 1.01" />
	</joint>
	<!-- to front -->
	<link name="pole_top_link">
		<visual>
			<geometry>
				<box size="0.36 0.04 0.04" />
			</geometry>
			<origin xyz="0.18 0.02 0.02" />
			<material name="pole_gray" />
		</visual>
		<collision>
			<geometry>
				<box size="0.36 0.04 0.04" />
			</geometry>
			<origin xyz="0.18 0.02 0.02" />
		</collision>
	</link>
	<joint name="pole_top2_joint" type="fixed">
		<parent link="pole_base_link" />
		<child link="pole_top2_link" />
		<origin rpy="0 0 1.57" xyz="0.04 0.04 1.01" />
	</joint>
	<!-- to left -->
	<link name="pole_top2_link">
		<visual>
			<geometry>
				<box size="0.31 0.04 0.04" />
			</geometry>
			<origin xyz="0.155 0.02 0.02" />
			<material name="pole_gray" />
		</visual>
		<collision>
			<geometry>
				<box size="0.31 0.04 0.04" />
			</geometry>
			<origin xyz="0.155 0.02 0.02" />
		</collision>
	</link>
	<!--<joint name="pole_camera_base_joint" type="fixed"> <parent link="pole_top2_link"/> <child link="pole_camera_link"/> <origin rpy="0 0.5 -1.57" xyz="0.14 -0.01 0"/> </joint> <link name="pole_camera_depth_frame"/> <link name="pole_camera_rgb_frame"/> <link name="pole_camera_depth_optical_frame"/> <link name="pole_camera_rgb_optical_frame"/> <link name="pole_camera_link"> <visual> <geometry> <box size="0.04 0.18 0.048"/> </geometry> <origin xyz="0 0 0"/> <material name="asus_xtion_gray"/> </visual> 
		<collision> <geometry> <box size="0.04 0.18 0.048"/> </geometry> <origin xyz="0 0 0"/> </collision> </link> <joint name="pole_camera_joint1" type="fixed"> <parent link="pole_camera_link"/> <child link="pole_camera_depth_frame"/> <origin rpy="0 0 0" xyz="0 0.049 0.013"/> </joint> <joint name="pole_camera_joint2" type="fixed"> <parent link="pole_camera_link"/> <child link="pole_camera_rgb_frame"/> <origin rpy="0 0 0" xyz="0 0.022 0.013"/> </joint> <joint name="pole_camera_joint3" type="fixed"> <parent 
		link="pole_camera_depth_frame"/> <child link="pole_camera_depth_optical_frame"/> <origin rpy="-1.57 0 -1.57" xyz="0 0 0"/> </joint> <joint name="pole_camera_joint4" type="fixed"> <parent link="pole_camera_rgb_frame"/> <child link="pole_camera_rgb_optical_frame"/> <origin rpy="-1.57 0 -1.57" xyz="0 0 0"/> </joint> -->

	<material name="lightGrey">
		<color rgba="0.7 0.7 0.7 1.0" />
	</material>

	<link name="wsg_adapter_link">
		<visual>
			<geometry>
				<cylinder length="0.027" radius="0.039" />
			</geometry>
			<material name="Grey" />
		</visual>
		<collision>
			<geometry>
				<cylinder length="0.027" radius="0.039" />
			</geometry>
		</collision>
	</link>

	<joint name="adapter_lbr_joint" type="fixed">
		<!--parent link="lbr_flange_link" / -->
		<parent link="lbr_flange_link" />
		<child link="wsg_adapter_link" />
		<!--insert_block name="origin"/ -->
		<!--origin xyz="0.0 0.0 0.0725" rpy="0 0 0"/ -->
		<!--<origin rpy="0 0 0" xyz="0.0 0.005 0.171"/> -->
		<origin rpy="0 0 0" xyz="0.0 0.0 0.0135" />
	</joint>
	
	<joint name="adapter_wsg_joint" type="fixed">
		<!--parent link="lbr_flange_link" / -->
		<parent link="wsg_adapter_link" />
		<child link="wsg_palm_frame" />
		<!--insert_block name="origin"/ -->
		<!--origin xyz="0.0 0.0 0.0725" rpy="0 0 0"/ -->
		<!--<origin rpy="0 0 0" xyz="0.0 0.005 0.171"/> -->
		<origin rpy="0 0 -0.785398" xyz="0.0 0.0 0.0135" />
	</joint>

	<link name="wsg_gripper_tip_frame">
	</link>

	<link name="wsg_gripper_l_tip_frame">
		<visual>
			<geometry>
				<mesh filename="package://wsg_description/meshes/grip_low_res.stl" />
			</geometry>
			<material name="lightGrey" />
			<origin rpy="-1.57 0 -1.57" xyz="0 -0.0185 -0.040" />
		</visual>
		<collision>
			<origin rpy="-1.57 0 -1.57" xyz="0 -0.0185 -0.040" />
			<geometry>
				<mesh filename="package://wsg_description/meshes/grip_low_res.stl" />
			</geometry>
		</collision>
	</link>

	<link name="wsg_gripper_r_tip_frame">
		<visual>
			<geometry>
				<mesh filename="package://wsg_description/meshes/grip_low_res.stl" />
			</geometry>
			<material name="lightGrey" />
			<origin rpy="-1.57 0 1.57" xyz="0 0.0185 -0.040" />
		</visual>
		<collision>
			<origin rpy="-1.57 0 1.57" xyz="0 0.0185 -0.040" />
			<geometry>
				<mesh filename="package://wsg_description/meshes/grip_low_res.stl" />
			</geometry>
		</collision>
	</link>

	<link name="wsg_palm_frame">
		<visual>
			<geometry>
				<mesh filename="package://wsg_description/meshes/palm_low_res.stl" />
			</geometry>
			<material name="lightGrey" />
			<origin rpy="0 0 0" xyz="0 0 0.0725" />
		</visual>
		<collision>
			<geometry>
				<mesh filename="package://wsg_description/meshes/palm_collision.stl" />
			</geometry>
			<material name="lightGrey" />
			<origin rpy="0 0 0" xyz="0 0 0.0725" />
		</collision>
	</link>

<!-- 	<!-- Connection to omnirob --> -->
<!-- 	<joint name="wsg_gripper_palm" type="fixed"> -->
<!-- 		<!--parent link="lbr_flange_link" / --> -->
<!-- 		<parent link="lbr_flange_link" /> -->
<!-- 		<child link="wsg_palm_frame" /> -->
<!-- 		<!--insert_block name="origin"/ --> -->
<!-- 		<!--origin xyz="0.0 0.0 0.0725" rpy="0 0 0"/ --> -->
<!-- 		<!--<origin rpy="0 0 0" xyz="0.0 0.005 0.171"/> --> -->
<!-- 		<origin rpy="0 0 -0.785398" xyz="0.0 0.0 0.0" /> -->
<!-- 	</joint> -->

	<joint name="wsg_gripper_tip" type="fixed">
		<parent link="wsg_palm_frame" />
		<child link="wsg_gripper_tip_frame" />
		<origin rpy="0 0 0" xyz="0.01 0.0 0.1085" />
		<!--origin xyz="0.0 0.0 0.0721" rpy="1.57 0 0"/ -->
	</joint>

	<joint name="wsg_gripper_l_tip" type="prismatic">
		<parent link="wsg_palm_frame" />
		<child link="wsg_gripper_l_tip_frame" />
		<axis xyz="-1 0 0" />
		<origin xyz="0 0 0.0725" rpy="0 0 0" />
		<limit lower="0.0" upper="0.07" effort="20" velocity="2.0" />
		<!--<limit effort="1000.0" lower="0.0" upper="0.09" velocity="0.2"/> -->
	</joint>

	<joint name="wsg_gripper_r_tip" type="prismatic">
		<parent link="wsg_palm_frame" />
		<child link="wsg_gripper_r_tip_frame" />
		<axis xyz="1 0 0" />
		<origin xyz="0 0 0.0725" rpy="0 0 0" />
		<limit lower="0.0" upper="0.07" effort="20" velocity="2.0" />
		<!--<limit effort="1000.0" lower="0.0" upper="0.09" velocity="0.2"/> -->
	</joint>

</robot>
