<?xml version="1.0" ?>
<!-- =================================================================================== -->
<!-- |    This document was autogenerated by xacro from omnirob.xacro                  | -->
<!-- |    EDITING THIS FILE BY HAND IS NOT RECOMMENDED                                 | -->
<!-- =================================================================================== -->
<robot name="omnirob" xmlns:xacro="http://ros.org/wiki/xacro">
  <!-- Import all Gazebo-customization elements, including Gazebo colors -->
  <!-- ros_control plugin -->
  <gazebo>
    <plugin filename="libgazebo_ros_control.so" name="gazebo_ros_control">
      <robotNamespace>/lbr</robotNamespace>
      <robotSimType>gazebo_ros_control/DefaultRobotHWSim</robotSimType>
    </plugin>
  </gazebo>
  <!-- Link0 -->
  <gazebo reference="lbr_0_link">
    <material>Gazebo/Blue</material>
  </gazebo>
  <!-- Link1 -->
  <gazebo reference="lbr_1_link">
    <material>Gazebo/Red</material>
  </gazebo>
  <!-- Link2 -->
  <gazebo reference="lbr_2_link">
    <material>Gazebo/Blue</material>
  </gazebo>
  <!-- Link3 -->
  <gazebo reference="lbr_3_link">
    <material>Gazebo/Red</material>
  </gazebo>
  <!-- Link4 -->
  <gazebo reference="lbr_4_link">
    <material>Gazebo/Blue</material>
  </gazebo>
  <!-- Link5 -->
  <gazebo reference="lbr_5_link">
    <material>Gazebo/Red</material>
  </gazebo>
  <!-- Link6 -->
  <gazebo reference="lbr_6_link">
    <material>Gazebo/Blue</material>
  </gazebo>
  <!-- Link7 -->
  <gazebo reference="lbr_7_link">
    <material>Gazebo/Red</material>
  </gazebo>
  <!-- Import Rviz colors -->
  <material name="Blue">
    <color rgba="0.0 0.0 0.8 1.0"/>
  </material>
  <material name="Green">
    <color rgba="0.0 0.8 0.0 1.0"/>
  </material>
  <material name="Grey">
    <color rgba="0.7 0.7 0.7 1.0"/>
  </material>
  <material name="Grey2">
    <color rgba="0.9 0.9 0.9 1.0"/>
  </material>
  <material name="Red">
    <color rgba="0.8 0.0 0.0 1.0"/>
  </material>
  <material name="orange">
    <color rgba="1.0 0.423529411765 0.0392156862745 1.0"/>
  </material>
  <material name="brown">
    <color rgba="0.870588235294 0.811764705882 0.764705882353 1.0"/>
  </material>
  <material name="White">
    <color rgba="1.0 1.0 1.0 1.0"/>
  </material>
  <material name="Black">
    <color rgba="0.0 0.0 0.0 1.0"/>
  </material>
  <material name="Gray">
    <color rgba="0.25 0.25 0.25 1.0"/>
  </material>
  <link name="base_link">
    <visual>
      <origin rpy="0 0 0" xyz="0 0 0"/>
      <geometry>
        <mesh filename="package://omnirob_description/meshes/omnirob_hull.stl" scale="0.001 0.001 0.001"/>
      </geometry>
      <material name="Gray"/>
    </visual>
    <collision>
      <origin rpy="0 0 0" xyz="0 0 0"/>
      <geometry>
        <mesh filename="package://omnirob_description/meshes/omnirob_hull_low_res.stl" scale="0.001 0.001 0.001"/>
      </geometry>
    </collision>
  </link>
  <link name="laser_front_link">
        </link>
  <link name="laser_rear_link">
        </link>
  <joint name="laser_front_joint" type="fixed">
    <parent link="base_link"/>
    <child link="laser_front_link"/>
    <origin rpy="0 0 -0.78893" xyz="0.542477 -0.317722 0.13664"/>
  </joint>
  <joint name="laser_rear_joint" type="fixed">
    <parent link="base_link"/>
    <child link="laser_rear_link"/>
    <origin rpy="0 0 2.31624" xyz="-0.534443 0.32895 0.13664"/>
  </joint>
  <!-- Used for fixing robot to Gazebo 'base_link' -->
  <!--<link name="world"/>
		
		<joint name="fixed" type="fixed">
		  <parent link="world"/>
		  <child link="${name}_0_link"/>
		</joint>-->
  <link name="lbr_0_link">
    <inertial>
      <origin rpy="0 0 0" xyz="0 0 0"/>
      <mass value="1.0"/>
      <inertia ixx="0.01" ixy="0" ixz="0" iyy="0.01" iyz="0" izz="0.01"/>
    </inertial>
    <visual>
      <origin rpy="0 0 0" xyz="0 0 0"/>
      <geometry>
        <mesh filename="package://omnirob_description/meshes/lbr0.stl"/>
      </geometry>
      <material name="Blue"/>
    </visual>
    <collision>
      <origin rpy="0 0 0" xyz="0 0 0"/>
      <geometry>
        <mesh filename="package://omnirob_description/meshes/lbr0_low_res.stl"/>
      </geometry>
    </collision>
  </link>
  <!-- joint between arm_0_link and arm_1_link -->
  <joint name="lbr_1_joint" type="revolute">
    <!--<origin xyz="0 0 0.14" rpy="0 0 -2.8407"/> -->
    <origin rpy="0 0 0" xyz="0 0 0.1105"/>
    <parent link="lbr_0_link"/>
    <child link="lbr_1_link"/>
    <axis xyz="0 0 1"/>
    <dynamics damping="25"/>
    <limit effort="200" lower="-2.9670" upper="2.9670" velocity="1.9634"/>
  </joint>
  <link name="lbr_1_link">
    <inertial>
      <origin rpy="0 0 0" xyz="0 0 0"/>
      <mass value="5.9907"/>
      <inertia ixx="0.01" ixy="0" ixz="0" iyy="0.01" iyz="0" izz="0.01"/>
    </inertial>
    <visual>
      <origin rpy="0 0 0" xyz="0 0 0"/>
      <geometry>
        <mesh filename="package://omnirob_description/meshes/lbr1.stl"/>
      </geometry>
      <material name="Blue"/>
    </visual>
    <collision>
      <origin rpy="0 0 0" xyz="0 0 0"/>
      <geometry>
        <mesh filename="package://omnirob_description/meshes/lbr1_low_res.stl"/>
      </geometry>
    </collision>
  </link>
  <!-- joint between arm_1_link and arm_2_link -->
  <joint name="lbr_2_joint" type="revolute">
    <origin rpy="1.5708 0 0" xyz="0 0 0.1915"/>
    <parent link="lbr_1_link"/>
    <child link="lbr_2_link"/>
    <axis xyz="0 0 1"/>
    <dynamics damping="25"/>
    <limit effort="200" lower="-2.0943" upper="2.0943" velocity="1.9634"/>
  </joint>
  <link name="lbr_2_link">
    <inertial>
      <origin rpy="0 0 0" xyz="0 0 0.002"/>
      <mass value="5.734939"/>
      <inertia ixx="0.03" ixy="0" ixz="0" iyy="0.03" iyz="0" izz="0.03"/>
    </inertial>
    <visual>
      <origin rpy="0 0 0" xyz="0 0 0.002"/>
      <geometry>
        <mesh filename="package://omnirob_description/meshes/lbr2.stl"/>
      </geometry>
      <material name="Red"/>
    </visual>
    <collision>
      <origin rpy="0 0 0" xyz="0 0 0.002"/>
      <geometry>
        <mesh filename="package://omnirob_description/meshes/lbr2_low_res.stl"/>
      </geometry>
    </collision>
  </link>
  <!-- joint between arm_2_link and arm_3_link -->
  <joint name="lbr_3_joint" type="revolute">
    <origin rpy="-1.5708 0 0" xyz="0 0.2085 0"/>
    <parent link="lbr_2_link"/>
    <child link="lbr_3_link"/>
    <axis xyz="0 0 1"/>
    <dynamics damping="25"/>
    <limit effort="100" lower="-2.9670" upper="2.9670" velocity="1.9634"/>
  </joint>
  <link name="lbr_3_link">
    <inertial>
      <origin rpy="0 0 0" xyz="0 -0.002 0"/>
      <mass value="4.214668"/>
      <inertia ixx="0.03" ixy="0" ixz="0" iyy="0.03" iyz="0" izz="0.03"/>
    </inertial>
    <visual>
      <origin rpy="0 0 0" xyz="0 -0.002 0"/>
      <geometry>
        <mesh filename="package://omnirob_description/meshes/lbr3.stl"/>
      </geometry>
      <material name="Blue"/>
    </visual>
    <collision>
      <origin rpy="0 0 0" xyz="0 -0.002 0"/>
      <geometry>
        <mesh filename="package://omnirob_description/meshes/lbr3_low_res.stl"/>
      </geometry>
    </collision>
  </link>
  <!-- joint between arm_3_link and arm_4_link -->
  <joint name="lbr_4_joint" type="revolute">
    <origin rpy="-1.5708 0 0" xyz="0 0 0.1915"/>
    <parent link="lbr_3_link"/>
    <child link="lbr_4_link"/>
    <axis xyz="0 0 1"/>
    <dynamics damping="25"/>
    <limit effort="100" lower="-2.0943" upper="2.0943" velocity="1.9634"/>
  </joint>
  <link name="lbr_4_link">
    <inertial>
      <origin rpy="0 0 0" xyz="0 0 0"/>
      <mass value="3.669819"/>
      <inertia ixx="0.03" ixy="0" ixz="0" iyy="0.03" iyz="0" izz="0.03"/>
    </inertial>
    <visual>
      <origin rpy="0 0 0" xyz="0 0 0"/>
      <geometry>
        <mesh filename="package://omnirob_description/meshes/lbr4.stl"/>
      </geometry>
      <material name="Red"/>
    </visual>
    <collision>
      <origin rpy="0 0 0" xyz="0 0 0"/>
      <geometry>
        <mesh filename="package://omnirob_description/meshes/lbr4_low_res.stl"/>
      </geometry>
    </collision>
  </link>
  <!-- joint between arm_4_link and arm_5_link -->
  <joint name="lbr_5_joint" type="revolute">
    <origin rpy="1.5708 0 0" xyz="0 -0.2085 0"/>
    <parent link="lbr_4_link"/>
    <child link="lbr_5_link"/>
    <axis xyz="0 0 1"/>
    <dynamics damping="25"/>
    <limit effort="100" lower="-2.9670" upper="2.9670" velocity="3.1415926"/>
  </joint>
  <link name="lbr_5_link">
    <inertial>
      <origin rpy="0 0 0" xyz="0 0 0"/>
      <mass value="2.313272"/>
      <inertia ixx="0.03" ixy="0" ixz="0" iyy="0.03" iyz="0" izz="0.03"/>
    </inertial>
    <visual>
      <origin rpy="0 0 0" xyz="0 0 0"/>
      <geometry>
        <mesh filename="package://omnirob_description/meshes/lbr5.stl"/>
      </geometry>
      <material name="Blue"/>
    </visual>
    <collision>
      <origin rpy="0 0 0" xyz="0 0 0"/>
      <geometry>
        <mesh filename="package://omnirob_description/meshes/lbr5_low_res.stl"/>
      </geometry>
    </collision>
  </link>
  <!-- joint between arm_5_link and arm_6_link -->
  <joint name="lbr_6_joint" type="revolute">
    <origin rpy="1.5708 0 0" xyz="0 0 0.1815"/>
    <parent link="lbr_5_link"/>
    <child link="lbr_6_link"/>
    <axis xyz="0 0 1"/>
    <dynamics damping="25"/>
    <limit effort="30" lower="-2.0943951" upper="2.0943951" velocity="1.9634"/>
  </joint>
  <link name="lbr_6_link">
    <inertial>
      <origin rpy="0 0 0" xyz="0 0 0"/>
      <mass value="2.057856"/>
      <inertia ixx="0.01" ixy="0" ixz="0" iyy="0.01" iyz="0" izz="0.01"/>
    </inertial>
    <visual>
      <origin rpy="0 0 0" xyz="0 0 -0.046"/>
      <geometry>
        <mesh filename="package://omnirob_description/meshes/lbr6.stl"/>
      </geometry>
      <material name="Red"/>
    </visual>
    <collision>
      <origin rpy="0 0 0" xyz="0 0 -0.046"/>
      <geometry>
        <mesh filename="package://omnirob_description/meshes/lbr6_low_res.stl"/>
      </geometry>
    </collision>
  </link>
  <!-- joint between arm_6_link and arm_7_link -->
  <joint name="lbr_7_joint" type="revolute">
    <origin rpy="-1.5708 0 0" xyz="0 0.057 0"/>
    <parent link="lbr_6_link"/>
    <child link="lbr_7_link"/>
    <axis xyz="0 0 1"/>
    <dynamics damping="25"/>
    <limit effort="30" lower="-2.9670" upper="2.9670" velocity="1.9634"/>
  </joint>
  <link name="lbr_7_link">
    <inertial>
      <origin rpy="0 0 0" xyz="0 0 0"/>
      <mass value="1.120198"/>
      <inertia ixx="0.01" ixy="0" ixz="0" iyy="0.01" iyz="0" izz="0.01"/>
    </inertial>
    <visual>
      <origin rpy="0 0 0" xyz="0 0 0"/>
      <geometry>
        <mesh filename="package://omnirob_description/meshes/lbr7.stl"/>
      </geometry>
      <material name="Blue"/>
    </visual>
    <collision>
      <origin rpy="0 0 0" xyz="0 0 0"/>
      <geometry>
        <mesh filename="package://omnirob_description/meshes/lbr7_low_res.stl"/>
      </geometry>
    </collision>
  </link>
  <joint name="flange" type="fixed">
    <parent link="lbr_7_link"/>
    <child link="lbr_flange_link"/>
    <origin rpy="0 0 0" xyz="0 0 0.0195"/>
  </joint>
  <link name="lbr_flange_link">
		</link>
  <transmission name="lbr_1_joint_trans">
    <type>pr2_mechanism_model/SimpleTransmission</type>
    <joint name="lbr_1_joint">
      <hardwareInterface>EffortJointInterface</hardwareInterface>
    </joint>
    <actuator name="lbr_1_joint_motor">
      <hardwareInterface>EffortJointInterface</hardwareInterface>
      <mechanicalReduction>1</mechanicalReduction>
    </actuator>
  </transmission>
  <transmission name="lbr_2_joint_trans">
    <type>pr2_mechanism_model/SimpleTransmission</type>
    <joint name="lbr_2_joint">
      <hardwareInterface>EffortJointInterface</hardwareInterface>
    </joint>
    <actuator name="lbr_2_joint_motor">
      <hardwareInterface>EffortJointInterface</hardwareInterface>
      <mechanicalReduction>1</mechanicalReduction>
    </actuator>
  </transmission>
  <transmission name="lbr_3_joint_trans">
    <type>pr2_mechanism_model/SimpleTransmission</type>
    <joint name="lbr_3_joint">
      <hardwareInterface>EffortJointInterface</hardwareInterface>
    </joint>
    <actuator name="lbr_3_joint_motor">
      <hardwareInterface>EffortJointInterface</hardwareInterface>
      <mechanicalReduction>1</mechanicalReduction>
    </actuator>
  </transmission>
  <transmission name="lbr_4_joint_trans">
    <type>pr2_mechanism_model/SimpleTransmission</type>
    <joint name="lbr_4_joint">
      <hardwareInterface>EffortJointInterface</hardwareInterface>
    </joint>
    <actuator name="lbr_4_joint_motor">
      <hardwareInterface>EffortJointInterface</hardwareInterface>
      <mechanicalReduction>1</mechanicalReduction>
    </actuator>
  </transmission>
  <transmission name="lbr_5_joint_trans">
    <type>pr2_mechanism_model/SimpleTransmission</type>
    <actuator name="lbr_5_joint_motor">
      <hardwareInterface>EffortJointInterface</hardwareInterface>
      <mechanicalReduction>1</mechanicalReduction>
    </actuator>
    <joint name="lbr_5_joint">
      <hardwareInterface>EffortJointInterface</hardwareInterface>
    </joint>
  </transmission>
  <transmission name="lbr_6_joint_trans">
    <type>pr2_mechanism_model/SimpleTransmission</type>
    <actuator name="lbr_6_joint_motor">
      <hardwareInterface>EffortJointInterface</hardwareInterface>
      <mechanicalReduction>1</mechanicalReduction>
    </actuator>
    <joint name="lbr_6_joint">
      <hardwareInterface>EffortJointInterface</hardwareInterface>
    </joint>
  </transmission>
  <transmission name="lbr_7_joint_trans">
    <type>pr2_mechanism_model/SimpleTransmission</type>
    <actuator name="lbr_7_joint_motor">
      <hardwareInterface>EffortJointInterface</hardwareInterface>
      <mechanicalReduction>1</mechanicalReduction>
    </actuator>
    <joint name="lbr_7_joint">
      <hardwareInterface>EffortJointInterface</hardwareInterface>
    </joint>
  </transmission>
  <joint name="omnirob_base_joint" type="fixed">
    <origin rpy="0 0 -1.5708" xyz="0.42 0.18 0.655"/>
    <parent link="base_link"/>
    <child link="lbr_0_link"/>
  </joint>
</robot>
